File: 30 90 .03ss 30tps Al Foil.csv
[Measurement conditions]
Sample identification,
Comment - 1,"Configuration=Reflection-transmission spinner, Owner=User-1, Creation date=5/11/2015 1:51:45 PM"
Comment - 2,"Goniometer=Theta/Theta; Minimum step size 2Theta:0.0001; Minimum step size Omega:0.0001"
Comment - 3,"Sample stage=Reflection-transmission spinner; Minimum step size Phi:0.1"
Comment - 4,"Diffractometer system=EMPYREAN"
Comment - 5,"Measurement program=C:\PANalytical\Data Collector\Programs\Esin Scan.xrdmp, Identifier={545BE9EB-C830-47C9-A564-E4EDE9967014}"
Anode material,Cu
K-Alpha1 wavelength,1.5405980
K-Alpha2 wavelength,1.5444260
Ratio K-Alpha2/K-Alpha1,0.500
Divergence slit,Fixed,0.19mm
Monochromator used,NO
Generator voltage, 45
Tube current, 40
File date and time,29/Jan/2020 11:27
Unit cell,
h k l, 0 0 0
Scan axis,Gonio
Scan range,20.000000001,89.986792989
Scan step size,0.0334225
No. of points, 2094
Scan type,CONTINUOUS
Phi,224.8
Time per step,29.845
[Scan points]
Angle,Intensity
20.016711270,187.0
20.083556344,163.0
20.150401419,178.0
20.217246493,156.0
20.284091568,171.0
20.350936642,162.0
20.417781717,163.0
20.484626791,137.0
20.551471866,141.0
20.618316940,140.0
20.685162015,163.0
20.752007089,143.0
20.818852164,148.0
20.885697238,145.0
20.952542313,135.0
21.019387387,137.0
21.086232462,144.0
21.153077536,146.0
21.219922611,143.0
21.286767685,162.0
21.353612760,139.0
21.420457834,146.0
21.487302909,161.0
21.554147983,135.0
21.620993058,149.0
21.687838132,133.0
21.754683207,138.0
21.821528281,127.0
21.888373356,147.0
21.955218430,144.0
22.022063505,124.0
22.088908579,129.0
22.155753654,151.0
22.222598728,156.0
22.289443803,141.0
22.356288877,141.0
22.423133952,132.0
22.489979026,125.0
22.556824100,122.0
22.623669175,121.0
22.690514249,140.0
22.757359324,129.0
22.824204398,138.0
22.891049473,137.0
22.957894547,148.0
23.024739622,125.0
23.091584696,108.0
23.158429771,124.0
23.225274845,121.0
23.292119920,145.0
23.358964994,127.0
23.425810069,103.0
23.492655143,108.0
23.559500218,136.0
23.626345292,121.0
23.693190367,117.0
23.760035441,141.0
23.826880516,119.0
23.893725590,124.0
23.960570665,121.0
24.027415739,110.0
24.094260814,121.0
24.161105888,145.0
24.227950963,109.0
24.294796037,110.0
24.361641112,126.0
24.428486186,121.0
24.495331261,119.0
24.562176335,136.0
24.629021410,108.0
24.695866484,108.0
24.762711559,116.0
24.829556633,105.0
24.896401708,115.0
24.963246782,124.0
25.030091856,107.0
25.096936931,107.0
25.163782005,107.0
25.230627080,109.0
25.297472154,111.0
25.364317229,124.0
25.431162303,119.0
25.498007378,141.0
25.564852452,120.0
25.631697527,117.0
25.698542601,121.0
25.765387676,121.0
25.832232750,100.0
25.899077825,107.0
25.965922899,96.0
26.032767974,119.0
26.099613048,109.0
26.166458123,110.0
26.233303197,103.0
26.300148272,110.0
26.366993346,110.0
26.433838421,108.0
26.500683495,115.0
26.567528570,115.0
26.634373644,108.0
26.701218719,91.0
26.768063793,115.0
26.834908868,102.0
26.901753942,98.0
26.968599017,99.0
27.035444091,93.0
27.102289166,103.0
27.169134240,124.0
27.235979315,108.0
27.302824389,135.0
27.369669464,102.0
27.436514538,104.0
27.503359612,123.0
27.570204687,104.0
27.637049761,95.0
27.703894836,104.0
27.770739910,121.0
27.837584985,98.0
27.904430059,112.0
27.971275134,100.0
28.038120208,135.0
28.104965283,116.0
28.171810357,120.0
28.238655432,150.0
28.305500506,124.0
28.372345581,114.0
28.439190655,103.0
28.506035730,98.0
28.572880804,98.0
28.639725879,88.0
28.706570953,79.0
28.773416028,96.0
28.840261102,105.0
28.907106177,105.0
28.973951251,99.0
29.040796326,96.0
29.107641400,104.0
29.174486475,108.0
29.241331549,129.0
29.308176624,115.0
29.375021698,95.0
29.441866773,79.0
29.508711847,101.0
29.575556922,98.0
29.642401996,105.0
29.709247071,114.0
29.776092145,97.0
29.842937219,105.0
29.909782294,104.0
29.976627368,105.0
30.043472443,108.0
30.110317517,102.0
30.177162592,110.0
30.244007666,89.0
30.310852741,88.0
30.377697815,100.0
30.444542890,85.0
30.511387964,98.0
30.578233039,83.0
30.645078113,87.0
30.711923188,88.0
30.778768262,97.0
30.845613337,85.0
30.912458411,99.0
30.979303486,96.0
31.046148560,90.0
31.112993635,99.0
31.179838709,89.0
31.246683784,99.0
31.313528858,90.0
31.380373933,78.0
31.447219007,78.0
31.514064082,108.0
31.580909156,74.0
31.647754231,109.0
31.714599305,107.0
31.781444380,107.0
31.848289454,80.0
31.915134529,79.0
31.981979603,91.0
32.048824678,97.0
32.115669752,85.0
32.182514827,99.0
32.249359901,87.0
32.316204975,83.0
32.383050050,78.0
32.449895124,83.0
32.516740199,104.0
32.583585273,99.0
32.650430348,92.0
32.717275422,89.0
32.784120497,76.0
32.850965571,91.0
32.917810646,103.0
32.984655720,96.0
33.051500795,87.0
33.118345869,88.0
33.185190944,92.0
33.252036018,98.0
33.318881093,89.0
33.385726167,75.0
33.452571242,87.0
33.519416316,92.0
33.586261391,92.0
33.653106465,87.0
33.719951540,99.0
33.786796614,92.0
33.853641689,84.0
33.920486763,88.0
33.987331838,103.0
34.054176912,89.0
34.121021987,81.0
34.187867061,90.0
34.254712136,99.0
34.321557210,72.0
34.388402285,101.0
34.455247359,86.0
34.522092434,86.0
34.588937508,98.0
34.655782583,93.0
34.722627657,101.0
34.789472731,77.0
34.856317806,92.0
34.923162880,92.0
34.990007955,96.0
35.056853029,99.0
35.123698104,101.0
35.190543178,89.0
35.257388253,87.0
35.324233327,98.0
35.391078402,89.0
35.457923476,83.0
35.524768551,79.0
35.591613625,73.0
35.658458700,83.0
35.725303774,79.0
35.792148849,73.0
35.858993923,77.0
35.925838998,103.0
35.992684072,99.0
36.059529147,97.0
36.126374221,90.0
36.193219296,100.0
36.260064370,87.0
36.326909445,78.0
36.393754519,68.0
36.460599594,97.0
36.527444668,89.0
36.594289743,79.0
36.661134817,89.0
36.727979892,81.0
36.794824966,85.0
36.861670041,84.0
36.928515115,103.0
36.995360190,108.0
37.062205264,87.0
37.129050339,91.0
37.195895413,83.0
37.262740487,79.0
37.329585562,87.0
37.396430636,74.0
37.463275711,92.0
37.530120785,79.0
37.596965860,95.0
37.663810934,86.0
37.730656009,85.0
37.797501083,98.0
37.864346158,92.0
37.931191232,122.0
37.998036307,172.0
38.064881381,902.0
38.131726456,2003.0
38.198571530,1526.0
38.265416605,1174.0
38.332261679,664.0
38.399106754,372.0
38.465951828,203.0
38.532796903,115.0
38.599641977,105.0
38.666487052,98.0
38.733332126,115.0
38.800177201,85.0
38.867022275,86.0
38.933867350,81.0
39.000712424,88.0
39.067557499,74.0
39.134402573,97.0
39.201247648,85.0
39.268092722,89.0
39.334937797,83.0
39.401782871,79.0
39.468627946,87.0
39.535473020,100.0
39.602318095,91.0
39.669163169,81.0
39.736008243,84.0
39.802853318,83.0
39.869698392,104.0
39.936543467,69.0
40.003388541,75.0
40.070233616,75.0
40.137078690,70.0
40.203923765,75.0
40.270768839,90.0
40.337613914,88.0
40.404458988,99.0
40.471304063,73.0
40.538149137,77.0
40.604994212,81.0
40.671839286,79.0
40.738684361,80.0
40.805529435,81.0
40.872374510,97.0
40.939219584,87.0
41.006064659,86.0
41.072909733,79.0
41.139754808,104.0
41.206599882,95.0
41.273444957,66.0
41.340290031,81.0
41.407135106,91.0
41.473980180,58.0
41.540825255,81.0
41.607670329,88.0
41.674515404,79.0
41.741360478,103.0
41.808205553,74.0
41.875050627,75.0
41.941895702,90.0
42.008740776,80.0
42.075585851,69.0
42.142430925,89.0
42.209275999,65.0
42.276121074,66.0
42.342966148,70.0
42.409811223,79.0
42.476656297,84.0
42.543501372,66.0
42.610346446,81.0
42.677191521,77.0
42.744036595,78.0
42.810881670,72.0
42.877726744,72.0
42.944571819,84.0
43.011416893,75.0
43.078261968,75.0
43.145107042,89.0
43.211952117,85.0
43.278797191,81.0
43.345642266,80.0
43.412487340,104.0
43.479332415,93.0
43.546177489,105.0
43.613022564,119.0
43.679867638,117.0
43.746712713,93.0
43.813557787,113.0
43.880402862,104.0
43.947247936,95.0
44.014093011,90.0
44.080938085,103.0
44.147783160,122.0
44.214628234,124.0
44.281473309,191.0
44.348318383,312.0
44.415163458,352.0
44.482008532,474.0
44.548853607,558.0
44.615698681,395.0
44.682543755,233.0
44.749388830,140.0
44.816233904,101.0
44.883078979,75.0
44.949924053,88.0
45.016769128,85.0
45.083614202,92.0
45.150459277,69.0
45.217304351,70.0
45.284149426,85.0
45.350994500,73.0
45.417839575,79.0
45.484684649,74.0
45.551529724,70.0
45.618374798,68.0
45.685219873,73.0
45.752064947,70.0
45.818910022,75.0
45.885755096,60.0
45.952600171,54.0
46.019445245,61.0
46.086290320,72.0
46.153135394,52.0
46.219980469,64.0
46.286825543,70.0
46.353670618,70.0
46.420515692,86.0
46.487360767,69.0
46.554205841,81.0
46.621050916,72.0
46.687895990,89.0
46.754741065,66.0
46.821586139,67.0
46.888431214,83.0
46.955276288,89.0
47.022121362,73.0
47.088966437,74.0
47.155811511,73.0
47.222656586,75.0
47.289501660,77.0
47.356346735,75.0
47.423191809,70.0
47.490036884,68.0
47.556881958,60.0
47.623727033,70.0
47.690572107,72.0
47.757417182,60.0
47.824262256,77.0
47.891107331,63.0
47.957952405,60.0
48.024797480,52.0
48.091642554,64.0
48.158487629,77.0
48.225332703,65.0
48.292177778,52.0
48.359022852,62.0
48.425867927,57.0
48.492713001,61.0
48.559558076,62.0
48.626403150,56.0
48.693248225,74.0
48.760093299,60.0
48.826938374,76.0
48.893783448,60.0
48.960628523,69.0
49.027473597,79.0
49.094318672,67.0
49.161163746,58.0
49.228008821,55.0
49.294853895,81.0
49.361698970,62.0
49.428544044,73.0
49.495389118,80.0
49.562234193,85.0
49.629079267,46.0
49.695924342,56.0
49.762769416,65.0
49.829614491,72.0
49.896459565,70.0
49.963304640,60.0
50.030149714,46.0
50.096994789,54.0
50.163839863,60.0
50.230684938,67.0
50.297530012,63.0
50.364375087,49.0
50.431220161,69.0
50.498065236,79.0
50.564910310,70.0
50.631755385,55.0
50.698600459,60.0
50.765445534,57.0
50.832290608,62.0
50.899135683,53.0
50.965980757,56.0
51.032825832,62.0
51.099670906,65.0
51.166515981,77.0
51.233361055,67.0
51.300206130,67.0
51.367051204,52.0
51.433896279,60.0
51.500741353,69.0
51.567586428,64.0
51.634431502,60.0
51.701276577,73.0
51.768121651,54.0
51.834966726,75.0
51.901811800,65.0
51.968656874,63.0
52.035501949,61.0
52.102347023,58.0
52.169192098,83.0
52.236037172,46.0
52.302882247,61.0
52.369727321,52.0
52.436572396,55.0
52.503417470,57.0
52.570262545,54.0
52.637107619,65.0
52.703952694,73.0
52.770797768,57.0
52.837642843,67.0
52.904487917,55.0
52.971332992,66.0
53.038178066,68.0
53.105023141,63.0
53.171868215,63.0
53.238713290,56.0
53.305558364,65.0
53.372403439,55.0
53.439248513,57.0
53.506093588,54.0
53.572938662,51.0
53.639783737,48.0
53.706628811,65.0
53.773473886,61.0
53.840318960,52.0
53.907164035,53.0
53.974009109,53.0
54.040854184,64.0
54.107699258,72.0
54.174544333,69.0
54.241389407,57.0
54.308234482,56.0
54.375079556,66.0
54.441924630,67.0
54.508769705,62.0
54.575614779,54.0
54.642459854,54.0
54.709304928,70.0
54.776150003,72.0
54.842995077,57.0
54.909840152,67.0
54.976685226,67.0
55.043530301,66.0
55.110375375,53.0
55.177220450,56.0
55.244065524,55.0
55.310910599,58.0
55.377755673,48.0
55.444600748,49.0
55.511445822,52.0
55.578290897,67.0
55.645135971,65.0
55.711981046,68.0
55.778826120,58.0
55.845671195,60.0
55.912516269,54.0
55.979361344,66.0
56.046206418,62.0
56.113051493,74.0
56.179896567,48.0
56.246741642,58.0
56.313586716,64.0
56.380431791,58.0
56.447276865,64.0
56.514121940,72.0
56.580967014,62.0
56.647812089,69.0
56.714657163,60.0
56.781502238,75.0
56.848347312,64.0
56.915192386,75.0
56.982037461,50.0
57.048882535,60.0
57.115727610,66.0
57.182572684,85.0
57.249417759,54.0
57.316262833,79.0
57.383107908,57.0
57.449952982,65.0
57.516798057,58.0
57.583643131,61.0
57.650488206,58.0
57.717333280,74.0
57.784178355,56.0
57.851023429,68.0
57.917868504,63.0
57.984713578,51.0
58.051558653,46.0
58.118403727,73.0
58.185248802,55.0
58.252093876,60.0
58.318938951,50.0
58.385784025,64.0
58.452629100,69.0
58.519474174,57.0
58.586319249,72.0
58.653164323,63.0
58.720009398,56.0
58.786854472,65.0
58.853699547,68.0
58.920544621,63.0
58.987389696,50.0
59.054234770,55.0
59.121079845,50.0
59.187924919,66.0
59.254769994,52.0
59.321615068,67.0
59.388460142,62.0
59.455305217,54.0
59.522150291,64.0
59.588995366,66.0
59.655840440,84.0
59.722685515,64.0
59.789530589,53.0
59.856375664,65.0
59.923220738,54.0
59.990065813,51.0
60.056910887,63.0
60.123755962,54.0
60.190601036,67.0
60.257446111,64.0
60.324291185,76.0
60.391136260,56.0
60.457981334,65.0
60.524826409,85.0
60.591671483,66.0
60.658516558,53.0
60.725361632,57.0
60.792206707,65.0
60.859051781,65.0
60.925896856,67.0
60.992741930,65.0
61.059587005,65.0
61.126432079,74.0
61.193277154,61.0
61.260122228,46.0
61.326967303,60.0
61.393812377,60.0
61.460657452,58.0
61.527502526,52.0
61.594347601,65.0
61.661192675,70.0
61.728037750,65.0
61.794882824,44.0
61.861727898,72.0
61.928572973,84.0
61.995418047,60.0
62.062263122,75.0
62.129108196,48.0
62.195953271,62.0
62.262798345,79.0
62.329643420,64.0
62.396488494,62.0
62.463333569,69.0
62.530178643,62.0
62.597023718,61.0
62.663868792,70.0
62.730713867,57.0
62.797558941,65.0
62.864404016,72.0
62.931249090,60.0
62.998094165,66.0
63.064939239,68.0
63.131784314,55.0
63.198629388,70.0
63.265474463,101.0
63.332319537,120.0
63.399164612,121.0
63.466009686,154.0
63.532854761,173.0
63.599699835,187.0
63.666544910,209.0
63.733389984,228.0
63.800235059,191.0
63.867080133,212.0
63.933925208,180.0
64.000770282,121.0
64.067615357,102.0
64.134460431,74.0
64.201305505,115.0
64.268150580,70.0
64.334995654,73.0
64.401840729,110.0
64.468685803,96.0
64.535530878,125.0
64.602375952,143.0
64.669221027,237.0
64.736066101,614.0
64.802911176,1368.0
64.869756250,1713.0
64.936601325,2369.0
65.003446399,1677.0
65.070291474,1179.0
65.137136548,1066.0
65.203981623,423.0
65.270826697,178.0
65.337671772,124.0
65.404516846,90.0
65.471361921,86.0
65.538206995,78.0
65.605052070,96.0
65.671897144,76.0
65.738742219,80.0
65.805587293,65.0
65.872432368,66.0
65.939277442,74.0
66.006122517,64.0
66.072967591,64.0
66.139812666,70.0
66.206657740,86.0
66.273502815,80.0
66.340347889,73.0
66.407192964,61.0
66.474038038,83.0
66.540883113,56.0
66.607728187,67.0
66.674573261,70.0
66.741418336,80.0
66.808263410,77.0
66.875108485,56.0
66.941953559,80.0
67.008798634,68.0
67.075643708,62.0
67.142488783,65.0
67.209333857,63.0
67.276178932,52.0
67.343024006,72.0
67.409869081,75.0
67.476714155,62.0
67.543559230,60.0
67.610404304,63.0
67.677249379,62.0
67.744094453,54.0
67.810939528,63.0
67.877784602,80.0
67.944629677,68.0
68.011474751,64.0
68.078319826,61.0
68.145164900,75.0
68.212009975,51.0
68.278855049,64.0
68.345700124,61.0
68.412545198,62.0
68.479390273,54.0
68.546235347,44.0
68.613080422,76.0
68.679925496,61.0
68.746770571,53.0
68.813615645,65.0
68.880460720,58.0
68.947305794,55.0
69.014150869,57.0
69.080995943,64.0
69.147841017,69.0
69.214686092,67.0
69.281531166,68.0
69.348376241,52.0
69.415221315,79.0
69.482066390,57.0
69.548911464,74.0
69.615756539,55.0
69.682601613,63.0
69.749446688,63.0
69.816291762,78.0
69.883136837,58.0
69.949981911,46.0
70.016826986,68.0
70.083672060,48.0
70.150517135,61.0
70.217362209,43.0
70.284207284,63.0
70.351052358,60.0
70.417897433,63.0
70.484742507,74.0
70.551587582,67.0
70.618432656,72.0
70.685277731,76.0
70.752122805,66.0
70.818967880,77.0
70.885812954,73.0
70.952658029,58.0
71.019503103,63.0
71.086348178,69.0
71.153193252,64.0
71.220038327,64.0
71.286883401,79.0
71.353728476,64.0
71.420573550,66.0
71.487418625,66.0
71.554263699,58.0
71.621108773,63.0
71.687953848,63.0
71.754798922,77.0
71.821643997,70.0
71.888489071,66.0
71.955334146,65.0
72.022179220,72.0
72.089024295,57.0
72.155869369,74.0
72.222714444,77.0
72.289559518,62.0
72.356404593,83.0
72.423249667,67.0
72.490094742,60.0
72.556939816,56.0
72.623784891,60.0
72.690629965,58.0
72.757475040,67.0
72.824320114,72.0
72.891165189,75.0
72.958010263,73.0
73.024855338,68.0
73.091700412,53.0
73.158545487,70.0
73.225390561,79.0
73.292235636,65.0
73.359080710,62.0
73.425925785,60.0
73.492770859,56.0
73.559615934,53.0
73.626461008,63.0
73.693306083,60.0
73.760151157,70.0
73.826996232,60.0
73.893841306,76.0
73.960686381,60.0
74.027531455,69.0
74.094376529,67.0
74.161221604,73.0
74.228066678,68.0
74.294911753,65.0
74.361756827,56.0
74.428601902,70.0
74.495446976,78.0
74.562292051,64.0
74.629137125,60.0
74.695982200,60.0
74.762827274,60.0
74.829672349,58.0
74.896517423,80.0
74.963362498,81.0
75.030207572,77.0
75.097052647,66.0
75.163897721,66.0
75.230742796,64.0
75.297587870,85.0
75.364432945,68.0
75.431278019,67.0
75.498123094,90.0
75.564968168,91.0
75.631813243,68.0
75.698658317,64.0
75.765503392,75.0
75.832348466,62.0
75.899193541,77.0
75.966038615,76.0
76.032883690,86.0
76.099728764,104.0
76.166573839,128.0
76.233418913,149.0
76.300263988,175.0
76.367109062,179.0
76.433954137,196.0
76.500799211,182.0
76.567644285,215.0
76.634489360,234.0
76.701334434,271.0
76.768179509,318.0
76.835024583,363.0
76.901869658,336.0
76.968714732,261.0
77.035559807,221.0
77.102404881,225.0
77.169249956,161.0
77.236095030,143.0
77.302940105,121.0
77.369785179,105.0
77.436630254,116.0
77.503475328,100.0
77.570320403,87.0
77.637165477,109.0
77.704010552,139.0
77.770855626,152.0
77.837700701,365.0
77.904545775,1129.0
77.971390850,1548.0
78.038235924,1679.0
78.105080999,1516.0
78.171926073,1237.0
78.238771148,1025.0
78.305616222,837.0
78.372461297,517.0
78.439306371,244.0
78.506151446,122.0
78.572996520,105.0
78.639841595,98.0
78.706686669,79.0
78.773531744,81.0
78.840376818,84.0
78.907221893,65.0
78.974066967,64.0
79.040912041,86.0
79.107757116,74.0
79.174602190,78.0
79.241447265,76.0
79.308292339,85.0
79.375137414,60.0
79.441982488,64.0
79.508827563,74.0
79.575672637,74.0
79.642517712,78.0
79.709362786,76.0
79.776207861,83.0
79.843052935,77.0
79.909898010,76.0
79.976743084,69.0
80.043588159,75.0
80.110433233,58.0
80.177278308,68.0
80.244123382,75.0
80.310968457,74.0
80.377813531,74.0
80.444658606,92.0
80.511503680,83.0
80.578348755,78.0
80.645193829,58.0
80.712038904,60.0
80.778883978,74.0
80.845729053,70.0
80.912574127,95.0
80.979419202,80.0
81.046264276,90.0
81.113109351,97.0
81.179954425,93.0
81.246799500,68.0
81.313644574,68.0
81.380489648,74.0
81.447334723,80.0
81.514179797,88.0
81.581024872,85.0
81.647869946,75.0
81.714715021,65.0
81.781560095,98.0
81.848405170,68.0
81.915250244,67.0
81.982095319,75.0
82.048940393,81.0
82.115785468,168.0
82.182630542,195.0
82.249475617,111.0
82.316320691,117.0
82.383165766,144.0
82.450010840,124.0
82.516855915,76.0
82.583700989,84.0
82.650546064,73.0
82.717391138,76.0
82.784236213,67.0
82.851081287,90.0
82.917926362,73.0
82.984771436,69.0
83.051616511,61.0
83.118461585,77.0
83.185306660,86.0
83.252151734,66.0
83.318996809,81.0
83.385841883,66.0
83.452686958,75.0
83.519532032,63.0
83.586377107,77.0
83.653222181,68.0
83.720067256,68.0
83.786912330,51.0
83.853757404,57.0
83.920602479,76.0
83.987447553,61.0
84.054292628,74.0
84.121137702,54.0
84.187982777,67.0
84.254827851,63.0
84.321672926,55.0
84.388518000,73.0
84.455363075,57.0
84.522208149,53.0
84.589053224,78.0
84.655898298,54.0
84.722743373,48.0
84.789588447,58.0
84.856433522,67.0
84.923278596,66.0
84.990123671,57.0
85.056968745,65.0
85.123813820,65.0
85.190658894,69.0
85.257503969,63.0
85.324349043,73.0
85.391194118,66.0
85.458039192,63.0
85.524884267,49.0
85.591729341,76.0
85.658574416,68.0
85.725419490,58.0
85.792264565,63.0
85.859109639,54.0
85.925954714,53.0
85.992799788,57.0
86.059644863,74.0
86.126489937,52.0
86.193335012,68.0
86.260180086,51.0
86.327025160,62.0
86.393870235,74.0
86.460715309,69.0
86.527560384,61.0
86.594405458,58.0
86.661250533,63.0
86.728095607,65.0
86.794940682,57.0
86.861785756,65.0
86.928630831,73.0
86.995475905,64.0
87.062320980,70.0
87.129166054,67.0
87.196011129,48.0
87.262856203,57.0
87.329701278,65.0
87.396546352,61.0
87.463391427,66.0
87.530236501,66.0
87.597081576,64.0
87.663926650,62.0
87.730771725,58.0
87.797616799,64.0
87.864461874,69.0
87.931306948,77.0
87.998152023,58.0
88.064997097,60.0
88.131842172,58.0
88.198687246,67.0
88.265532321,68.0
88.332377395,56.0
88.399222470,58.0
88.466067544,61.0
88.532912619,69.0
88.599757693,57.0
88.666602768,69.0
88.733447842,74.0
88.800292916,55.0
88.867137991,88.0
88.933983065,56.0
89.000828140,66.0
89.067673214,81.0
89.134518289,67.0
89.201363363,55.0
89.268208438,69.0
89.335053512,58.0
89.401898587,87.0
89.468743661,66.0
89.535588736,56.0
89.602433810,68.0
89.669278885,51.0
89.736123959,67.0
89.802969034,61.0
89.869814108,49.0
89.936659183,62.0
89.970081720,67.0