File: 30 90 .03ss 30tps Mortan Salt Grinded+Al powder.csv
[Measurement conditions]
Sample identification,
Comment - 1,"Configuration=Reflection-transmission spinner, Owner=User-1, Creation date=5/11/2015 1:51:45 PM"
Comment - 2,"Goniometer=Theta/Theta; Minimum step size 2Theta:0.0001; Minimum step size Omega:0.0001"
Comment - 3,"Sample stage=Reflection-transmission spinner; Minimum step size Phi:0.1"
Comment - 4,"Diffractometer system=EMPYREAN"
Comment - 5,"Measurement program=C:\PANalytical\Data Collector\Programs\Esin Scan.xrdmp, Identifier={545BE9EB-C830-47C9-A564-E4EDE9967014}"
Anode material,Cu
K-Alpha1 wavelength,1.5405980
K-Alpha2 wavelength,1.5444260
Ratio K-Alpha2/K-Alpha1,0.500
Divergence slit,Fixed,0.19mm
Monochromator used,NO
Generator voltage, 45
Tube current, 40
File date and time,29/Jan/2020 11:09
Unit cell,
h k l, 0 0 0
Scan axis,Gonio
Scan range,20.000000001,89.986792989
Scan step size,0.0334225
No. of points, 2094
Scan type,CONTINUOUS
Phi,210.3
Time per step,29.845
[Scan points]
Angle,Intensity
20.016711270,175.0
20.083556344,150.0
20.150401419,152.0
20.217246493,156.0
20.284091568,147.0
20.350936642,156.0
20.417781717,133.0
20.484626791,125.0
20.551471866,132.0
20.618316940,136.0
20.685162015,129.0
20.752007089,124.0
20.818852164,126.0
20.885697238,138.0
20.952542313,131.0
21.019387387,134.0
21.086232462,128.0
21.153077536,138.0
21.219922611,127.0
21.286767685,115.0
21.353612760,107.0
21.420457834,147.0
21.487302909,123.0
21.554147983,138.0
21.620993058,128.0
21.687838132,120.0
21.754683207,136.0
21.821528281,105.0
21.888373356,107.0
21.955218430,132.0
22.022063505,99.0
22.088908579,136.0
22.155753654,105.0
22.222598728,103.0
22.289443803,134.0
22.356288877,123.0
22.423133952,120.0
22.489979026,101.0
22.556824100,125.0
22.623669175,108.0
22.690514249,100.0
22.757359324,101.0
22.824204398,102.0
22.891049473,134.0
22.957894547,115.0
23.024739622,99.0
23.091584696,102.0
23.158429771,107.0
23.225274845,111.0
23.292119920,116.0
23.358964994,104.0
23.425810069,104.0
23.492655143,104.0
23.559500218,91.0
23.626345292,102.0
23.693190367,90.0
23.760035441,114.0
23.826880516,111.0
23.893725590,107.0
23.960570665,109.0
24.027415739,99.0
24.094260814,99.0
24.161105888,113.0
24.227950963,95.0
24.294796037,110.0
24.361641112,107.0
24.428486186,116.0
24.495331261,90.0
24.562176335,116.0
24.629021410,105.0
24.695866484,93.0
24.762711559,91.0
24.829556633,86.0
24.896401708,109.0
24.963246782,95.0
25.030091856,112.0
25.096936931,111.0
25.163782005,83.0
25.230627080,103.0
25.297472154,54.0
25.364317229,92.0
25.431162303,95.0
25.498007378,97.0
25.564852452,109.0
25.631697527,107.0
25.698542601,109.0
25.765387676,83.0
25.832232750,73.0
25.899077825,97.0
25.965922899,85.0
26.032767974,89.0
26.099613048,81.0
26.166458123,87.0
26.233303197,75.0
26.300148272,85.0
26.366993346,107.0
26.433838421,97.0
26.500683495,90.0
26.567528570,98.0
26.634373644,111.0
26.701218719,92.0
26.768063793,109.0
26.834908868,186.0
26.901753942,279.0
26.968599017,375.0
27.035444091,279.0
27.102289166,254.0
27.169134240,250.0
27.235979315,240.0
27.302824389,183.0
27.369669464,129.0
27.436514538,88.0
27.503359612,95.0
27.570204687,95.0
27.637049761,105.0
27.703894836,86.0
27.770739910,72.0
27.837584985,74.0
27.904430059,79.0
27.971275134,81.0
28.038120208,79.0
28.104965283,81.0
28.171810357,93.0
28.238655432,87.0
28.305500506,74.0
28.372345581,89.0
28.439190655,70.0
28.506035730,72.0
28.572880804,90.0
28.639725879,67.0
28.706570953,69.0
28.773416028,83.0
28.840261102,66.0
28.907106177,85.0
28.973951251,80.0
29.040796326,88.0
29.107641400,88.0
29.174486475,50.0
29.241331549,68.0
29.308176624,61.0
29.375021698,63.0
29.441866773,75.0
29.508711847,76.0
29.575556922,66.0
29.642401996,66.0
29.709247071,74.0
29.776092145,80.0
29.842937219,61.0
29.909782294,69.0
29.976627368,70.0
30.043472443,77.0
30.110317517,72.0
30.177162592,61.0
30.244007666,70.0
30.310852741,95.0
30.377697815,89.0
30.444542890,72.0
30.511387964,92.0
30.578233039,93.0
30.645078113,78.0
30.711923188,86.0
30.778768262,88.0
30.845613337,108.0
30.912458411,111.0
30.979303486,161.0
31.046148560,322.0
31.112993635,1212.0
31.179838709,2129.0
31.246683784,3804.0
31.313528858,5165.0
31.380373933,4004.0
31.447219007,2930.0
31.514064082,2267.0
31.580909156,2446.0
31.647754231,1607.0
31.714599305,701.0
31.781444380,221.0
31.848289454,145.0
31.915134529,107.0
31.981979603,105.0
32.048824678,98.0
32.115669752,87.0
32.182514827,101.0
32.249359901,88.0
32.316204975,83.0
32.383050050,77.0
32.449895124,86.0
32.516740199,81.0
32.583585273,86.0
32.650430348,61.0
32.717275422,77.0
32.784120497,83.0
32.850965571,73.0
32.917810646,79.0
32.984655720,53.0
33.051500795,58.0
33.118345869,67.0
33.185190944,72.0
33.252036018,60.0
33.318881093,60.0
33.385726167,61.0
33.452571242,57.0
33.519416316,63.0
33.586261391,64.0
33.653106465,63.0
33.719951540,60.0
33.786796614,65.0
33.853641689,69.0
33.920486763,62.0
33.987331838,61.0
34.054176912,63.0
34.121021987,51.0
34.187867061,66.0
34.254712136,62.0
34.321557210,51.0
34.388402285,65.0
34.455247359,60.0
34.522092434,55.0
34.588937508,66.0
34.655782583,49.0
34.722627657,60.0
34.789472731,66.0
34.856317806,60.0
34.923162880,46.0
34.990007955,64.0
35.056853029,60.0
35.123698104,50.0
35.190543178,74.0
35.257388253,54.0
35.324233327,66.0
35.391078402,70.0
35.457923476,45.0
35.524768551,66.0
35.591613625,57.0
35.658458700,46.0
35.725303774,67.0
35.792148849,51.0
35.858993923,56.0
35.925838998,66.0
35.992684072,61.0
36.059529147,62.0
36.126374221,61.0
36.193219296,39.0
36.260064370,58.0
36.326909445,57.0
36.393754519,61.0
36.460599594,75.0
36.527444668,60.0
36.594289743,55.0
36.661134817,53.0
36.727979892,49.0
36.794824966,56.0
36.861670041,51.0
36.928515115,56.0
36.995360190,51.0
37.062205264,58.0
37.129050339,56.0
37.195895413,62.0
37.262740487,69.0
37.329585562,65.0
37.396430636,60.0
37.463275711,63.0
37.530120785,58.0
37.596965860,38.0
37.663810934,65.0
37.730656009,76.0
37.797501083,122.0
37.864346158,184.0
37.931191232,428.0
37.998036307,1054.0
38.064881381,1556.0
38.131726456,1401.0
38.198571530,912.0
38.265416605,601.0
38.332261679,614.0
38.399106754,442.0
38.465951828,232.0
38.532796903,87.0
38.599641977,67.0
38.666487052,51.0
38.733332126,70.0
38.800177201,45.0
38.867022275,54.0
38.933867350,60.0
39.000712424,50.0
39.067557499,68.0
39.134402573,41.0
39.201247648,42.0
39.268092722,45.0
39.334937797,61.0
39.401782871,43.0
39.468627946,45.0
39.535473020,50.0
39.602318095,60.0
39.669163169,48.0
39.736008243,50.0
39.802853318,51.0
39.869698392,52.0
39.936543467,49.0
40.003388541,54.0
40.070233616,55.0
40.137078690,56.0
40.203923765,55.0
40.270768839,56.0
40.337613914,52.0
40.404458988,54.0
40.471304063,56.0
40.538149137,50.0
40.604994212,54.0
40.671839286,44.0
40.738684361,63.0
40.805529435,44.0
40.872374510,58.0
40.939219584,64.0
41.006064659,44.0
41.072909733,48.0
41.139754808,53.0
41.206599882,49.0
41.273444957,50.0
41.340290031,54.0
41.407135106,53.0
41.473980180,51.0
41.540825255,55.0
41.607670329,50.0
41.674515404,44.0
41.741360478,63.0
41.808205553,55.0
41.875050627,52.0
41.941895702,48.0
42.008740776,56.0
42.075585851,30.0
42.142430925,41.0
42.209275999,56.0
42.276121074,57.0
42.342966148,51.0
42.409811223,51.0
42.476656297,48.0
42.543501372,49.0
42.610346446,44.0
42.677191521,52.0
42.744036595,58.0
42.810881670,45.0
42.877726744,46.0
42.944571819,60.0
43.011416893,49.0
43.078261968,50.0
43.145107042,45.0
43.211952117,27.0
43.278797191,41.0
43.345642266,54.0
43.412487340,51.0
43.479332415,57.0
43.546177489,49.0
43.613022564,56.0
43.679867638,60.0
43.746712713,53.0
43.813557787,64.0
43.880402862,64.0
43.947247936,74.0
44.014093011,60.0
44.080938085,105.0
44.147783160,190.0
44.214628234,334.0
44.281473309,742.0
44.348318383,759.0
44.415163458,655.0
44.482008532,479.0
44.548853607,336.0
44.615698681,275.0
44.682543755,239.0
44.749388830,241.0
44.816233904,333.0
44.883078979,512.0
44.949924053,1051.0
45.016769128,2921.0
45.083614202,3504.0
45.150459277,2766.0
45.217304351,1943.0
45.284149426,1178.0
45.350994500,804.0
45.417839575,597.0
45.484684649,286.0
45.551529724,151.0
45.618374798,114.0
45.685219873,97.0
45.752064947,75.0
45.818910022,76.0
45.885755096,69.0
45.952600171,58.0
46.019445245,57.0
46.086290320,55.0
46.153135394,73.0
46.219980469,48.0
46.286825543,65.0
46.353670618,57.0
46.420515692,43.0
46.487360767,48.0
46.554205841,43.0
46.621050916,49.0
46.687895990,43.0
46.754741065,56.0
46.821586139,50.0
46.888431214,44.0
46.955276288,42.0
47.022121362,62.0
47.088966437,43.0
47.155811511,46.0
47.222656586,45.0
47.289501660,39.0
47.356346735,36.0
47.423191809,48.0
47.490036884,46.0
47.556881958,46.0
47.623727033,42.0
47.690572107,29.0
47.757417182,43.0
47.824262256,46.0
47.891107331,60.0
47.957952405,36.0
48.024797480,44.0
48.091642554,31.0
48.158487629,33.0
48.225332703,49.0
48.292177778,39.0
48.359022852,40.0
48.425867927,58.0
48.492713001,44.0
48.559558076,46.0
48.626403150,30.0
48.693248225,43.0
48.760093299,41.0
48.826938374,43.0
48.893783448,49.0
48.960628523,45.0
49.027473597,33.0
49.094318672,52.0
49.161163746,45.0
49.228008821,43.0
49.294853895,36.0
49.361698970,55.0
49.428544044,30.0
49.495389118,48.0
49.562234193,45.0
49.629079267,42.0
49.695924342,38.0
49.762769416,32.0
49.829614491,45.0
49.896459565,42.0
49.963304640,48.0
50.030149714,36.0
50.096994789,46.0
50.163839863,37.0
50.230684938,48.0
50.297530012,39.0
50.364375087,44.0
50.431220161,41.0
50.498065236,48.0
50.564910310,46.0
50.631755385,38.0
50.698600459,42.0
50.765445534,44.0
50.832290608,40.0
50.899135683,37.0
50.965980757,41.0
51.032825832,36.0
51.099670906,38.0
51.166515981,31.0
51.233361055,42.0
51.300206130,27.0
51.367051204,45.0
51.433896279,39.0
51.500741353,36.0
51.567586428,28.0
51.634431502,29.0
51.701276577,39.0
51.768121651,38.0
51.834966726,28.0
51.901811800,42.0
51.968656874,45.0
52.035501949,52.0
52.102347023,32.0
52.169192098,39.0
52.236037172,45.0
52.302882247,42.0
52.369727321,29.0
52.436572396,38.0
52.503417470,39.0
52.570262545,33.0
52.637107619,41.0
52.703952694,33.0
52.770797768,48.0
52.837642843,39.0
52.904487917,39.0
52.971332992,42.0
53.038178066,46.0
53.105023141,29.0
53.171868215,40.0
53.238713290,57.0
53.305558364,66.0
53.372403439,73.0
53.439248513,92.0
53.506093588,100.0
53.572938662,103.0
53.639783737,104.0
53.706628811,89.0
53.773473886,70.0
53.840318960,51.0
53.907164035,46.0
53.974009109,51.0
54.040854184,33.0
54.107699258,42.0
54.174544333,37.0
54.241389407,43.0
54.308234482,55.0
54.375079556,34.0
54.441924630,57.0
54.508769705,36.0
54.575614779,41.0
54.642459854,28.0
54.709304928,30.0
54.776150003,33.0
54.842995077,43.0
54.909840152,27.0
54.976685226,43.0
55.043530301,44.0
55.110375375,33.0
55.177220450,37.0
55.244065524,39.0
55.310910599,38.0
55.377755673,41.0
55.444600748,41.0
55.511445822,34.0
55.578290897,39.0
55.645135971,58.0
55.711981046,61.0
55.778826120,73.0
55.845671195,112.0
55.912516269,202.0
55.979361344,357.0
56.046206418,574.0
56.113051493,548.0
56.179896567,571.0
56.246741642,487.0
56.313586716,349.0
56.380431791,275.0
56.447276865,194.0
56.514121940,137.0
56.580967014,108.0
56.647812089,77.0
56.714657163,39.0
56.781502238,32.0
56.848347312,60.0
56.915192386,45.0
56.982037461,34.0
57.048882535,33.0
57.115727610,39.0
57.182572684,30.0
57.249417759,36.0
57.316262833,36.0
57.383107908,40.0
57.449952982,40.0
57.516798057,43.0
57.583643131,32.0
57.650488206,34.0
57.717333280,24.0
57.784178355,33.0
57.851023429,31.0
57.917868504,30.0
57.984713578,44.0
58.051558653,27.0
58.118403727,28.0
58.185248802,45.0
58.252093876,41.0
58.318938951,33.0
58.385784025,39.0
58.452629100,36.0
58.519474174,29.0
58.586319249,28.0
58.653164323,26.0
58.720009398,30.0
58.786854472,36.0
58.853699547,48.0
58.920544621,40.0
58.987389696,31.0
59.054234770,32.0
59.121079845,34.0
59.187924919,29.0
59.254769994,34.0
59.321615068,53.0
59.388460142,41.0
59.455305217,26.0
59.522150291,28.0
59.588995366,26.0
59.655840440,40.0
59.722685515,31.0
59.789530589,43.0
59.856375664,43.0
59.923220738,29.0
59.990065813,34.0
60.056910887,20.0
60.123755962,24.0
60.190601036,31.0
60.257446111,31.0
60.324291185,33.0
60.391136260,29.0
60.457981334,29.0
60.524826409,31.0
60.591671483,38.0
60.658516558,26.0
60.725361632,34.0
60.792206707,32.0
60.859051781,26.0
60.925896856,38.0
60.992741930,22.0
61.059587005,27.0
61.126432079,41.0
61.193277154,30.0
61.260122228,41.0
61.326967303,32.0
61.393812377,30.0
61.460657452,40.0
61.527502526,38.0
61.594347601,32.0
61.661192675,31.0
61.728037750,25.0
61.794882824,29.0
61.861727898,38.0
61.928572973,31.0
61.995418047,34.0
62.062263122,37.0
62.129108196,42.0
62.195953271,44.0
62.262798345,39.0
62.329643420,37.0
62.396488494,29.0
62.463333569,29.0
62.530178643,26.0
62.597023718,38.0
62.663868792,32.0
62.730713867,30.0
62.797558941,33.0
62.864404016,27.0
62.931249090,39.0
62.998094165,48.0
63.064939239,39.0
63.131784314,30.0
63.198629388,30.0
63.265474463,38.0
63.332319537,31.0
63.399164612,30.0
63.466009686,43.0
63.532854761,31.0
63.599699835,42.0
63.666544910,45.0
63.733389984,44.0
63.800235059,45.0
63.867080133,43.0
63.933925208,39.0
64.000770282,53.0
64.067615357,40.0
64.134460431,40.0
64.201305505,46.0
64.268150580,41.0
64.334995654,41.0
64.401840729,45.0
64.468685803,40.0
64.535530878,81.0
64.602375952,154.0
64.669221027,340.0
64.736066101,430.0
64.802911176,282.0
64.869756250,308.0
64.936601325,281.0
65.003446399,185.0
65.070291474,120.0
65.137136548,98.0
65.203981623,69.0
65.270826697,49.0
65.337671772,44.0
65.404516846,46.0
65.471361921,67.0
65.538206995,66.0
65.605052070,90.0
65.671897144,120.0
65.738742219,242.0
65.805587293,474.0
65.872432368,505.0
65.939277442,407.0
66.006122517,428.0
66.072967591,344.0
66.139812666,199.0
66.206657740,147.0
66.273502815,100.0
66.340347889,105.0
66.407192964,72.0
66.474038038,56.0
66.540883113,36.0
66.607728187,40.0
66.674573261,43.0
66.741418336,55.0
66.808263410,42.0
66.875108485,40.0
66.941953559,39.0
67.008798634,36.0
67.075643708,36.0
67.142488783,31.0
67.209333857,33.0
67.276178932,48.0
67.343024006,37.0
67.409869081,37.0
67.476714155,33.0
67.543559230,37.0
67.610404304,33.0
67.677249379,40.0
67.744094453,34.0
67.810939528,28.0
67.877784602,32.0
67.944629677,38.0
68.011474751,34.0
68.078319826,37.0
68.145164900,29.0
68.212009975,33.0
68.278855049,27.0
68.345700124,37.0
68.412545198,22.0
68.479390273,37.0
68.546235347,30.0
68.613080422,37.0
68.679925496,36.0
68.746770571,31.0
68.813615645,29.0
68.880460720,29.0
68.947305794,27.0
69.014150869,37.0
69.080995943,42.0
69.147841017,51.0
69.214686092,38.0
69.281531166,33.0
69.348376241,39.0
69.415221315,38.0
69.482066390,27.0
69.548911464,36.0
69.615756539,39.0
69.682601613,30.0
69.749446688,29.0
69.816291762,31.0
69.883136837,43.0
69.949981911,33.0
70.016826986,40.0
70.083672060,28.0
70.150517135,38.0
70.217362209,44.0
70.284207284,34.0
70.351052358,38.0
70.417897433,45.0
70.484742507,34.0
70.551587582,32.0
70.618432656,49.0
70.685277731,40.0
70.752122805,38.0
70.818967880,50.0
70.885812954,44.0
70.952658029,39.0
71.019503103,30.0
71.086348178,32.0
71.153193252,38.0
71.220038327,31.0
71.286883401,28.0
71.353728476,42.0
71.420573550,39.0
71.487418625,30.0
71.554263699,34.0
71.621108773,42.0
71.687953848,40.0
71.754798922,46.0
71.821643997,31.0
71.888489071,31.0
71.955334146,39.0
72.022179220,45.0
72.089024295,40.0
72.155869369,38.0
72.222714444,42.0
72.289559518,25.0
72.356404593,56.0
72.423249667,32.0
72.490094742,38.0
72.556939816,66.0
72.623784891,62.0
72.690629965,81.0
72.757475040,78.0
72.824320114,75.0
72.891165189,67.0
72.958010263,61.0
73.024855338,54.0
73.091700412,44.0
73.158545487,44.0
73.225390561,42.0
73.292235636,48.0
73.359080710,34.0
73.425925785,50.0
73.492770859,43.0
73.559615934,37.0
73.626461008,25.0
73.693306083,48.0
73.760151157,49.0
73.826996232,34.0
73.893841306,51.0
73.960686381,43.0
74.027531455,41.0
74.094376529,36.0
74.161221604,42.0
74.228066678,52.0
74.294911753,68.0
74.361756827,52.0
74.428601902,73.0
74.495446976,58.0
74.562292051,67.0
74.629137125,99.0
74.695982200,136.0
74.762827274,219.0
74.829672349,375.0
74.896517423,539.0
74.963362498,494.0
75.030207572,456.0
75.097052647,514.0
75.163897721,442.0
75.230742796,323.0
75.297587870,225.0
75.364432945,186.0
75.431278019,132.0
75.498123094,80.0
75.564968168,84.0
75.631813243,57.0
75.698658317,57.0
75.765503392,51.0
75.832348466,49.0
75.899193541,46.0
75.966038615,38.0
76.032883690,45.0
76.099728764,55.0
76.166573839,41.0
76.233418913,50.0
76.300263988,54.0
76.367109062,45.0
76.433954137,28.0
76.500799211,40.0
76.567644285,38.0
76.634489360,43.0
76.701334434,46.0
76.768179509,50.0
76.835024583,45.0
76.901869658,54.0
76.968714732,44.0
77.035559807,43.0
77.102404881,33.0
77.169249956,40.0
77.236095030,36.0
77.302940105,42.0
77.369785179,53.0
77.436630254,54.0
77.503475328,40.0
77.570320403,61.0
77.637165477,68.0
77.704010552,93.0
77.770855626,175.0
77.837700701,444.0
77.904545775,440.0
77.971390850,291.0
78.038235924,301.0
78.105080999,389.0
78.171926073,212.0
78.238771148,152.0
78.305616222,116.0
78.372461297,88.0
78.439306371,69.0
78.506151446,53.0
78.572996520,43.0
78.639841595,56.0
78.706686669,41.0
78.773531744,62.0
78.840376818,48.0
78.907221893,39.0
78.974066967,46.0
79.040912041,34.0
79.107757116,36.0
79.174602190,42.0
79.241447265,44.0
79.308292339,25.0
79.375137414,45.0
79.441982488,38.0
79.508827563,48.0
79.575672637,40.0
79.642517712,44.0
79.709362786,49.0
79.776207861,48.0
79.843052935,43.0
79.909898010,36.0
79.976743084,42.0
80.043588159,34.0
80.110433233,31.0
80.177278308,39.0
80.244123382,30.0
80.310968457,49.0
80.377813531,39.0
80.444658606,40.0
80.511503680,45.0
80.578348755,34.0
80.645193829,48.0
80.712038904,38.0
80.778883978,34.0
80.845729053,30.0
80.912574127,46.0
80.979419202,43.0
81.046264276,41.0
81.113109351,44.0
81.179954425,33.0
81.246799500,24.0
81.313644574,36.0
81.380489648,42.0
81.447334723,39.0
81.514179797,61.0
81.581024872,46.0
81.647869946,36.0
81.714715021,53.0
81.781560095,40.0
81.848405170,54.0
81.915250244,53.0
81.982095319,74.0
82.048940393,146.0
82.115785468,192.0
82.182630542,102.0
82.249475617,110.0
82.316320691,146.0
82.383165766,119.0
82.450010840,63.0
82.516855915,55.0
82.583700989,57.0
82.650546064,43.0
82.717391138,29.0
82.784236213,45.0
82.851081287,34.0
82.917926362,42.0
82.984771436,51.0
83.051616511,58.0
83.118461585,53.0
83.185306660,66.0
83.252151734,64.0
83.318996809,88.0
83.385841883,99.0
83.452686958,135.0
83.519532032,220.0
83.586377107,393.0
83.653222181,548.0
83.720067256,419.0
83.786912330,325.0
83.853757404,372.0
83.920602479,372.0
83.987447553,257.0
84.054292628,158.0
84.121137702,136.0
84.187982777,96.0
84.254827851,63.0
84.321672926,54.0
84.388518000,75.0
84.455363075,46.0
84.522208149,46.0
84.589053224,41.0
84.655898298,51.0
84.722743373,29.0
84.789588447,53.0
84.856433522,32.0
84.923278596,45.0
84.990123671,41.0
85.056968745,31.0
85.123813820,38.0
85.190658894,40.0
85.257503969,29.0
85.324349043,38.0
85.391194118,55.0
85.458039192,28.0
85.524884267,41.0
85.591729341,43.0
85.658574416,40.0
85.725419490,38.0
85.792264565,48.0
85.859109639,27.0
85.925954714,38.0
85.992799788,39.0
86.059644863,43.0
86.126489937,36.0
86.193335012,36.0
86.260180086,34.0
86.327025160,37.0
86.393870235,31.0
86.460715309,39.0
86.527560384,32.0
86.594405458,31.0
86.661250533,30.0
86.728095607,41.0
86.794940682,29.0
86.861785756,34.0
86.928630831,39.0
86.995475905,33.0
87.062320980,33.0
87.129166054,42.0
87.196011129,32.0
87.262856203,28.0
87.329701278,26.0
87.396546352,28.0
87.463391427,27.0
87.530236501,42.0
87.597081576,38.0
87.663926650,29.0
87.730771725,40.0
87.797616799,20.0
87.864461874,51.0
87.931306948,37.0
87.998152023,37.0
88.064997097,36.0
88.131842172,39.0
88.198687246,25.0
88.265532321,39.0
88.332377395,40.0
88.399222470,27.0
88.466067544,31.0
88.532912619,32.0
88.599757693,30.0
88.666602768,37.0
88.733447842,40.0
88.800292916,27.0
88.867137991,26.0
88.933983065,36.0
89.000828140,38.0
89.067673214,38.0
89.134518289,28.0
89.201363363,24.0
89.268208438,37.0
89.335053512,27.0
89.401898587,45.0
89.468743661,24.0
89.535588736,36.0
89.602433810,32.0
89.669278885,29.0
89.736123959,33.0
89.802969034,40.0
89.869814108,48.0
89.936659183,51.0
89.970081720,48.0