File: 30 90 .03ss 30tps Mortan Salt Grinded.csv
[Measurement conditions]
Sample identification,
Comment - 1,"Configuration=Reflection-transmission spinner, Owner=User-1, Creation date=5/11/2015 1:51:45 PM"
Comment - 2,"Goniometer=Theta/Theta; Minimum step size 2Theta:0.0001; Minimum step size Omega:0.0001"
Comment - 3,"Sample stage=Reflection-transmission spinner; Minimum step size Phi:0.1"
Comment - 4,"Diffractometer system=EMPYREAN"
Comment - 5,"Measurement program=C:\PANalytical\Data Collector\Programs\Esin Scan.xrdmp, Identifier={545BE9EB-C830-47C9-A564-E4EDE9967014}"
Anode material,Cu
K-Alpha1 wavelength,1.5405980
K-Alpha2 wavelength,1.5444260
Ratio K-Alpha2/K-Alpha1,0.500
Divergence slit,Fixed,0.19mm
Monochromator used,NO
Generator voltage, 45
Tube current, 40
File date and time,29/Jan/2020 10:55
Unit cell,
h k l, 0 0 0
Scan axis,Gonio
Scan range,20.000000001,89.986792989
Scan step size,0.0334225
No. of points, 2094
Scan type,CONTINUOUS
Phi,286.4
Time per step,29.845
[Scan points]
Angle,Intensity
20.016711270,135.0
20.083556344,124.0
20.150401419,141.0
20.217246493,119.0
20.284091568,109.0
20.350936642,120.0
20.417781717,111.0
20.484626791,119.0
20.551471866,120.0
20.618316940,114.0
20.685162015,132.0
20.752007089,119.0
20.818852164,127.0
20.885697238,112.0
20.952542313,112.0
21.019387387,135.0
21.086232462,127.0
21.153077536,104.0
21.219922611,100.0
21.286767685,128.0
21.353612760,125.0
21.420457834,129.0
21.487302909,148.0
21.554147983,122.0
21.620993058,121.0
21.687838132,110.0
21.754683207,114.0
21.821528281,119.0
21.888373356,128.0
21.955218430,91.0
22.022063505,113.0
22.088908579,96.0
22.155753654,129.0
22.222598728,111.0
22.289443803,125.0
22.356288877,115.0
22.423133952,120.0
22.489979026,108.0
22.556824100,103.0
22.623669175,88.0
22.690514249,117.0
22.757359324,107.0
22.824204398,93.0
22.891049473,112.0
22.957894547,113.0
23.024739622,93.0
23.091584696,100.0
23.158429771,120.0
23.225274845,93.0
23.292119920,117.0
23.358964994,91.0
23.425810069,110.0
23.492655143,91.0
23.559500218,110.0
23.626345292,89.0
23.693190367,116.0
23.760035441,95.0
23.826880516,110.0
23.893725590,95.0
23.960570665,101.0
24.027415739,102.0
24.094260814,111.0
24.161105888,90.0
24.227950963,102.0
24.294796037,111.0
24.361641112,93.0
24.428486186,89.0
24.495331261,89.0
24.562176335,107.0
24.629021410,96.0
24.695866484,99.0
24.762711559,97.0
24.829556633,85.0
24.896401708,87.0
24.963246782,79.0
25.030091856,95.0
25.096936931,100.0
25.163782005,87.0
25.230627080,97.0
25.297472154,73.0
25.364317229,84.0
25.431162303,109.0
25.498007378,84.0
25.564852452,69.0
25.631697527,84.0
25.698542601,93.0
25.765387676,76.0
25.832232750,86.0
25.899077825,99.0
25.965922899,80.0
26.032767974,85.0
26.099613048,95.0
26.166458123,86.0
26.233303197,90.0
26.300148272,102.0
26.366993346,86.0
26.433838421,72.0
26.500683495,93.0
26.567528570,84.0
26.634373644,87.0
26.701218719,84.0
26.768063793,96.0
26.834908868,86.0
26.901753942,93.0
26.968599017,74.0
27.035444091,86.0
27.102289166,180.0
27.169134240,334.0
27.235979315,621.0
27.302824389,894.0
27.369669464,638.0
27.436514538,278.0
27.503359612,150.0
27.570204687,103.0
27.637049761,119.0
27.703894836,89.0
27.770739910,86.0
27.837584985,76.0
27.904430059,93.0
27.971275134,90.0
28.038120208,76.0
28.104965283,72.0
28.171810357,66.0
28.238655432,69.0
28.305500506,70.0
28.372345581,87.0
28.439190655,67.0
28.506035730,73.0
28.572880804,80.0
28.639725879,68.0
28.706570953,84.0
28.773416028,91.0
28.840261102,64.0
28.907106177,68.0
28.973951251,86.0
29.040796326,74.0
29.107641400,92.0
29.174486475,90.0
29.241331549,65.0
29.308176624,80.0
29.375021698,87.0
29.441866773,74.0
29.508711847,84.0
29.575556922,76.0
29.642401996,78.0
29.709247071,68.0
29.776092145,100.0
29.842937219,60.0
29.909782294,68.0
29.976627368,87.0
30.043472443,86.0
30.110317517,73.0
30.177162592,85.0
30.244007666,88.0
30.310852741,84.0
30.377697815,70.0
30.444542890,84.0
30.511387964,96.0
30.578233039,87.0
30.645078113,87.0
30.711923188,103.0
30.778768262,86.0
30.845613337,85.0
30.912458411,95.0
30.979303486,97.0
31.046148560,120.0
31.112993635,127.0
31.179838709,150.0
31.246683784,172.0
31.313528858,266.0
31.380373933,445.0
31.447219007,1594.0
31.514064082,6593.0
31.580909156,10820.0
31.647754231,11157.0
31.714599305,5968.0
31.781444380,2041.0
31.848289454,541.0
31.915134529,279.0
31.981979603,194.0
32.048824678,158.0
32.115669752,170.0
32.182514827,140.0
32.249359901,102.0
32.316204975,111.0
32.383050050,90.0
32.449895124,88.0
32.516740199,92.0
32.583585273,91.0
32.650430348,88.0
32.717275422,72.0
32.784120497,86.0
32.850965571,68.0
32.917810646,79.0
32.984655720,75.0
33.051500795,76.0
33.118345869,73.0
33.185190944,73.0
33.252036018,55.0
33.318881093,65.0
33.385726167,61.0
33.452571242,74.0
33.519416316,60.0
33.586261391,84.0
33.653106465,81.0
33.719951540,69.0
33.786796614,58.0
33.853641689,72.0
33.920486763,63.0
33.987331838,63.0
34.054176912,75.0
34.121021987,62.0
34.187867061,69.0
34.254712136,67.0
34.321557210,51.0
34.388402285,58.0
34.455247359,54.0
34.522092434,68.0
34.588937508,62.0
34.655782583,63.0
34.722627657,55.0
34.789472731,52.0
34.856317806,50.0
34.923162880,50.0
34.990007955,64.0
35.056853029,60.0
35.123698104,70.0
35.190543178,56.0
35.257388253,65.0
35.324233327,42.0
35.391078402,60.0
35.457923476,60.0
35.524768551,60.0
35.591613625,66.0
35.658458700,57.0
35.725303774,56.0
35.792148849,53.0
35.858993923,49.0
35.925838998,49.0
35.992684072,52.0
36.059529147,51.0
36.126374221,48.0
36.193219296,65.0
36.260064370,48.0
36.326909445,56.0
36.393754519,45.0
36.460599594,61.0
36.527444668,60.0
36.594289743,65.0
36.661134817,57.0
36.727979892,49.0
36.794824966,60.0
36.861670041,57.0
36.928515115,31.0
36.995360190,49.0
37.062205264,65.0
37.129050339,65.0
37.195895413,46.0
37.262740487,52.0
37.329585562,55.0
37.396430636,67.0
37.463275711,40.0
37.530120785,50.0
37.596965860,31.0
37.663810934,56.0
37.730656009,55.0
37.797501083,51.0
37.864346158,41.0
37.931191232,42.0
37.998036307,50.0
38.064881381,46.0
38.131726456,36.0
38.198571530,45.0
38.265416605,52.0
38.332261679,87.0
38.399106754,128.0
38.465951828,63.0
38.532796903,65.0
38.599641977,58.0
38.666487052,51.0
38.733332126,66.0
38.800177201,41.0
38.867022275,53.0
38.933867350,43.0
39.000712424,43.0
39.067557499,42.0
39.134402573,58.0
39.201247648,52.0
39.268092722,46.0
39.334937797,58.0
39.401782871,49.0
39.468627946,48.0
39.535473020,50.0
39.602318095,41.0
39.669163169,44.0
39.736008243,62.0
39.802853318,45.0
39.869698392,48.0
39.936543467,44.0
40.003388541,49.0
40.070233616,40.0
40.137078690,40.0
40.203923765,44.0
40.270768839,39.0
40.337613914,51.0
40.404458988,37.0
40.471304063,50.0
40.538149137,30.0
40.604994212,56.0
40.671839286,48.0
40.738684361,58.0
40.805529435,34.0
40.872374510,54.0
40.939219584,61.0
41.006064659,54.0
41.072909733,38.0
41.139754808,46.0
41.206599882,52.0
41.273444957,41.0
41.340290031,38.0
41.407135106,52.0
41.473980180,36.0
41.540825255,48.0
41.607670329,30.0
41.674515404,40.0
41.741360478,36.0
41.808205553,36.0
41.875050627,37.0
41.941895702,40.0
42.008740776,43.0
42.075585851,48.0
42.142430925,39.0
42.209275999,41.0
42.276121074,44.0
42.342966148,50.0
42.409811223,38.0
42.476656297,32.0
42.543501372,43.0
42.610346446,54.0
42.677191521,41.0
42.744036595,36.0
42.810881670,49.0
42.877726744,49.0
42.944571819,50.0
43.011416893,39.0
43.078261968,55.0
43.145107042,55.0
43.211952117,55.0
43.278797191,44.0
43.345642266,39.0
43.412487340,45.0
43.479332415,53.0
43.546177489,51.0
43.613022564,44.0
43.679867638,61.0
43.746712713,54.0
43.813557787,42.0
43.880402862,49.0
43.947247936,66.0
44.014093011,42.0
44.080938085,60.0
44.147783160,52.0
44.214628234,44.0
44.281473309,50.0
44.348318383,57.0
44.415163458,45.0
44.482008532,60.0
44.548853607,86.0
44.615698681,91.0
44.682543755,88.0
44.749388830,81.0
44.816233904,74.0
44.883078979,74.0
44.949924053,108.0
45.016769128,157.0
45.083614202,258.0
45.150459277,411.0
45.217304351,1079.0
45.284149426,2482.0
45.350994500,3876.0
45.417839575,3509.0
45.484684649,2576.0
45.551529724,1253.0
45.618374798,457.0
45.685219873,253.0
45.752064947,143.0
45.818910022,113.0
45.885755096,110.0
45.952600171,69.0
46.019445245,78.0
46.086290320,75.0
46.153135394,64.0
46.219980469,69.0
46.286825543,55.0
46.353670618,62.0
46.420515692,57.0
46.487360767,66.0
46.554205841,67.0
46.621050916,51.0
46.687895990,45.0
46.754741065,39.0
46.821586139,48.0
46.888431214,46.0
46.955276288,54.0
47.022121362,55.0
47.088966437,58.0
47.155811511,40.0
47.222656586,42.0
47.289501660,49.0
47.356346735,45.0
47.423191809,49.0
47.490036884,48.0
47.556881958,48.0
47.623727033,43.0
47.690572107,60.0
47.757417182,49.0
47.824262256,38.0
47.891107331,46.0
47.957952405,33.0
48.024797480,33.0
48.091642554,32.0
48.158487629,34.0
48.225332703,41.0
48.292177778,38.0
48.359022852,37.0
48.425867927,38.0
48.492713001,33.0
48.559558076,42.0
48.626403150,40.0
48.693248225,39.0
48.760093299,28.0
48.826938374,37.0
48.893783448,32.0
48.960628523,43.0
49.027473597,40.0
49.094318672,43.0
49.161163746,41.0
49.228008821,37.0
49.294853895,37.0
49.361698970,41.0
49.428544044,29.0
49.495389118,36.0
49.562234193,36.0
49.629079267,30.0
49.695924342,30.0
49.762769416,41.0
49.829614491,24.0
49.896459565,43.0
49.963304640,31.0
50.030149714,33.0
50.096994789,42.0
50.163839863,28.0
50.230684938,34.0
50.297530012,48.0
50.364375087,36.0
50.431220161,38.0
50.498065236,51.0
50.564910310,49.0
50.631755385,26.0
50.698600459,40.0
50.765445534,29.0
50.832290608,40.0
50.899135683,44.0
50.965980757,50.0
51.032825832,37.0
51.099670906,40.0
51.166515981,49.0
51.233361055,41.0
51.300206130,39.0
51.367051204,36.0
51.433896279,34.0
51.500741353,36.0
51.567586428,29.0
51.634431502,39.0
51.701276577,53.0
51.768121651,44.0
51.834966726,38.0
51.901811800,28.0
51.968656874,25.0
52.035501949,45.0
52.102347023,34.0
52.169192098,38.0
52.236037172,36.0
52.302882247,50.0
52.369727321,33.0
52.436572396,32.0
52.503417470,44.0
52.570262545,31.0
52.637107619,38.0
52.703952694,28.0
52.770797768,44.0
52.837642843,33.0
52.904487917,36.0
52.971332992,28.0
53.038178066,34.0
53.105023141,39.0
53.171868215,33.0
53.238713290,37.0
53.305558364,36.0
53.372403439,33.0
53.439248513,53.0
53.506093588,27.0
53.572938662,51.0
53.639783737,72.0
53.706628811,146.0
53.773473886,183.0
53.840318960,171.0
53.907164035,135.0
53.974009109,92.0
54.040854184,65.0
54.107699258,42.0
54.174544333,45.0
54.241389407,55.0
54.308234482,43.0
54.375079556,37.0
54.441924630,38.0
54.508769705,39.0
54.575614779,26.0
54.642459854,48.0
54.709304928,29.0
54.776150003,39.0
54.842995077,42.0
54.909840152,33.0
54.976685226,44.0
55.043530301,39.0
55.110375375,40.0
55.177220450,39.0
55.244065524,43.0
55.310910599,33.0
55.377755673,27.0
55.444600748,41.0
55.511445822,37.0
55.578290897,40.0
55.645135971,50.0
55.711981046,38.0
55.778826120,39.0
55.845671195,61.0
55.912516269,52.0
55.979361344,58.0
56.046206418,72.0
56.113051493,88.0
56.179896567,159.0
56.246741642,368.0
56.313586716,690.0
56.380431791,944.0
56.447276865,877.0
56.514121940,732.0
56.580967014,479.0
56.647812089,239.0
56.714657163,120.0
56.781502238,69.0
56.848347312,67.0
56.915192386,44.0
56.982037461,51.0
57.048882535,53.0
57.115727610,48.0
57.182572684,42.0
57.249417759,38.0
57.316262833,43.0
57.383107908,33.0
57.449952982,30.0
57.516798057,44.0
57.583643131,53.0
57.650488206,38.0
57.717333280,41.0
57.784178355,39.0
57.851023429,41.0
57.917868504,28.0
57.984713578,33.0
58.051558653,38.0
58.118403727,37.0
58.185248802,32.0
58.252093876,36.0
58.318938951,29.0
58.385784025,24.0
58.452629100,36.0
58.519474174,28.0
58.586319249,26.0
58.653164323,49.0
58.720009398,30.0
58.786854472,40.0
58.853699547,28.0
58.920544621,46.0
58.987389696,31.0
59.054234770,33.0
59.121079845,32.0
59.187924919,24.0
59.254769994,32.0
59.321615068,34.0
59.388460142,28.0
59.455305217,29.0
59.522150291,27.0
59.588995366,33.0
59.655840440,40.0
59.722685515,29.0
59.789530589,36.0
59.856375664,36.0
59.923220738,38.0
59.990065813,29.0
60.056910887,39.0
60.123755962,36.0
60.190601036,26.0
60.257446111,40.0
60.324291185,33.0
60.391136260,32.0
60.457981334,36.0
60.524826409,37.0
60.591671483,27.0
60.658516558,29.0
60.725361632,38.0
60.792206707,42.0
60.859051781,37.0
60.925896856,29.0
60.992741930,31.0
61.059587005,31.0
61.126432079,38.0
61.193277154,36.0
61.260122228,29.0
61.326967303,28.0
61.393812377,27.0
61.460657452,27.0
61.527502526,31.0
61.594347601,30.0
61.661192675,25.0
61.728037750,37.0
61.794882824,32.0
61.861727898,37.0
61.928572973,21.0
61.995418047,34.0
62.062263122,45.0
62.129108196,34.0
62.195953271,34.0
62.262798345,29.0
62.329643420,31.0
62.396488494,29.0
62.463333569,37.0
62.530178643,36.0
62.597023718,22.0
62.663868792,33.0
62.730713867,41.0
62.797558941,24.0
62.864404016,39.0
62.931249090,25.0
62.998094165,31.0
63.064939239,33.0
63.131784314,44.0
63.198629388,36.0
63.265474463,40.0
63.332319537,39.0
63.399164612,30.0
63.466009686,41.0
63.532854761,37.0
63.599699835,28.0
63.666544910,33.0
63.733389984,40.0
63.800235059,29.0
63.867080133,26.0
63.933925208,29.0
64.000770282,39.0
64.067615357,34.0
64.134460431,33.0
64.201305505,30.0
64.268150580,32.0
64.334995654,29.0
64.401840729,29.0
64.468685803,49.0
64.535530878,41.0
64.602375952,36.0
64.669221027,39.0
64.736066101,36.0
64.802911176,31.0
64.869756250,33.0
64.936601325,37.0
65.003446399,58.0
65.070291474,37.0
65.137136548,58.0
65.203981623,32.0
65.270826697,34.0
65.337671772,25.0
65.404516846,48.0
65.471361921,43.0
65.538206995,38.0
65.605052070,48.0
65.671897144,53.0
65.738742219,49.0
65.805587293,44.0
65.872432368,76.0
65.939277442,104.0
66.006122517,222.0
66.072967591,460.0
66.139812666,553.0
66.206657740,413.0
66.273502815,373.0
66.340347889,326.0
66.407192964,191.0
66.474038038,83.0
66.540883113,65.0
66.607728187,52.0
66.674573261,39.0
66.741418336,49.0
66.808263410,39.0
66.875108485,36.0
66.941953559,41.0
67.008798634,51.0
67.075643708,54.0
67.142488783,43.0
67.209333857,41.0
67.276178932,46.0
67.343024006,32.0
67.409869081,41.0
67.476714155,27.0
67.543559230,20.0
67.610404304,27.0
67.677249379,29.0
67.744094453,38.0
67.810939528,48.0
67.877784602,44.0
67.944629677,32.0
68.011474751,31.0
68.078319826,25.0
68.145164900,37.0
68.212009975,42.0
68.278855049,37.0
68.345700124,44.0
68.412545198,44.0
68.479390273,34.0
68.546235347,30.0
68.613080422,30.0
68.679925496,37.0
68.746770571,38.0
68.813615645,27.0
68.880460720,30.0
68.947305794,34.0
69.014150869,30.0
69.080995943,33.0
69.147841017,29.0
69.214686092,30.0
69.281531166,46.0
69.348376241,22.0
69.415221315,41.0
69.482066390,45.0
69.548911464,38.0
69.615756539,39.0
69.682601613,29.0
69.749446688,34.0
69.816291762,39.0
69.883136837,26.0
69.949981911,37.0
70.016826986,28.0
70.083672060,45.0
70.150517135,36.0
70.217362209,30.0
70.284207284,49.0
70.351052358,27.0
70.417897433,41.0
70.484742507,51.0
70.551587582,32.0
70.618432656,32.0
70.685277731,33.0
70.752122805,30.0
70.818967880,41.0
70.885812954,45.0
70.952658029,32.0
71.019503103,32.0
71.086348178,32.0
71.153193252,38.0
71.220038327,27.0
71.286883401,53.0
71.353728476,28.0
71.420573550,32.0
71.487418625,36.0
71.554263699,39.0
71.621108773,52.0
71.687953848,25.0
71.754798922,45.0
71.821643997,29.0
71.888489071,36.0
71.955334146,37.0
72.022179220,28.0
72.089024295,40.0
72.155869369,37.0
72.222714444,36.0
72.289559518,30.0
72.356404593,30.0
72.423249667,30.0
72.490094742,33.0
72.556939816,30.0
72.623784891,50.0
72.690629965,29.0
72.757475040,42.0
72.824320114,54.0
72.891165189,66.0
72.958010263,102.0
73.024855338,76.0
73.091700412,76.0
73.158545487,80.0
73.225390561,58.0
73.292235636,64.0
73.359080710,41.0
73.425925785,58.0
73.492770859,57.0
73.559615934,44.0
73.626461008,20.0
73.693306083,36.0
73.760151157,36.0
73.826996232,36.0
73.893841306,42.0
73.960686381,29.0
74.027531455,31.0
74.094376529,33.0
74.161221604,51.0
74.228066678,53.0
74.294911753,39.0
74.361756827,51.0
74.428601902,63.0
74.495446976,40.0
74.562292051,43.0
74.629137125,53.0
74.695982200,63.0
74.762827274,67.0
74.829672349,76.0
74.896517423,121.0
74.963362498,156.0
75.030207572,280.0
75.097052647,602.0
75.163897721,958.0
75.230742796,815.0
75.297587870,616.0
75.364432945,611.0
75.431278019,530.0
75.498123094,323.0
75.564968168,184.0
75.631813243,104.0
75.698658317,100.0
75.765503392,79.0
75.832348466,66.0
75.899193541,61.0
75.966038615,60.0
76.032883690,45.0
76.099728764,43.0
76.166573839,50.0
76.233418913,60.0
76.300263988,50.0
76.367109062,48.0
76.433954137,55.0
76.500799211,41.0
76.567644285,44.0
76.634489360,44.0
76.701334434,54.0
76.768179509,49.0
76.835024583,42.0
76.901869658,45.0
76.968714732,48.0
77.035559807,41.0
77.102404881,49.0
77.169249956,41.0
77.236095030,34.0
77.302940105,45.0
77.369785179,37.0
77.436630254,34.0
77.503475328,43.0
77.570320403,39.0
77.637165477,48.0
77.704010552,41.0
77.770855626,37.0
77.837700701,43.0
77.904545775,28.0
77.971390850,32.0
78.038235924,40.0
78.105080999,36.0
78.171926073,33.0
78.238771148,38.0
78.305616222,41.0
78.372461297,37.0
78.439306371,40.0
78.506151446,41.0
78.572996520,46.0
78.639841595,42.0
78.706686669,31.0
78.773531744,32.0
78.840376818,32.0
78.907221893,34.0
78.974066967,40.0
79.040912041,45.0
79.107757116,20.0
79.174602190,29.0
79.241447265,38.0
79.308292339,36.0
79.375137414,42.0
79.441982488,37.0
79.508827563,36.0
79.575672637,39.0
79.642517712,29.0
79.709362786,38.0
79.776207861,36.0
79.843052935,36.0
79.909898010,31.0
79.976743084,33.0
80.043588159,26.0
80.110433233,33.0
80.177278308,36.0
80.244123382,46.0
80.310968457,30.0
80.377813531,29.0
80.444658606,43.0
80.511503680,22.0
80.578348755,34.0
80.645193829,29.0
80.712038904,39.0
80.778883978,32.0
80.845729053,53.0
80.912574127,39.0
80.979419202,29.0
81.046264276,45.0
81.113109351,27.0
81.179954425,38.0
81.246799500,32.0
81.313644574,41.0
81.380489648,29.0
81.447334723,38.0
81.514179797,49.0
81.581024872,36.0
81.647869946,21.0
81.714715021,43.0
81.781560095,42.0
81.848405170,37.0
81.915250244,48.0
81.982095319,28.0
82.048940393,29.0
82.115785468,37.0
82.182630542,41.0
82.249475617,46.0
82.316320691,44.0
82.383165766,40.0
82.450010840,33.0
82.516855915,30.0
82.583700989,42.0
82.650546064,42.0
82.717391138,50.0
82.784236213,58.0
82.851081287,49.0
82.917926362,39.0
82.984771436,29.0
83.051616511,39.0
83.118461585,50.0
83.185306660,51.0
83.252151734,45.0
83.318996809,44.0
83.385841883,52.0
83.452686958,61.0
83.519532032,62.0
83.586377107,83.0
83.653222181,101.0
83.720067256,195.0
83.786912330,332.0
83.853757404,526.0
83.920602479,551.0
83.987447553,463.0
84.054292628,372.0
84.121137702,356.0
84.187982777,315.0
84.254827851,252.0
84.321672926,128.0
84.388518000,99.0
84.455363075,67.0
84.522208149,57.0
84.589053224,63.0
84.655898298,28.0
84.722743373,42.0
84.789588447,45.0
84.856433522,41.0
84.923278596,43.0
84.990123671,39.0
85.056968745,45.0
85.123813820,40.0
85.190658894,36.0
85.257503969,40.0
85.324349043,44.0
85.391194118,32.0
85.458039192,42.0
85.524884267,36.0
85.591729341,43.0
85.658574416,38.0
85.725419490,42.0
85.792264565,39.0
85.859109639,40.0
85.925954714,37.0
85.992799788,44.0
86.059644863,37.0
86.126489937,36.0
86.193335012,27.0
86.260180086,43.0
86.327025160,41.0
86.393870235,32.0
86.460715309,43.0
86.527560384,25.0
86.594405458,31.0
86.661250533,36.0
86.728095607,34.0
86.794940682,33.0
86.861785756,32.0
86.928630831,30.0
86.995475905,28.0
87.062320980,18.0
87.129166054,29.0
87.196011129,37.0
87.262856203,25.0
87.329701278,39.0
87.396546352,28.0
87.463391427,31.0
87.530236501,37.0
87.597081576,28.0
87.663926650,36.0
87.730771725,29.0
87.797616799,39.0
87.864461874,32.0
87.931306948,33.0
87.998152023,34.0
88.064997097,34.0
88.131842172,29.0
88.198687246,20.0
88.265532321,26.0
88.332377395,27.0
88.399222470,42.0
88.466067544,38.0
88.532912619,30.0
88.599757693,36.0
88.666602768,31.0
88.733447842,31.0
88.800292916,36.0
88.867137991,28.0
88.933983065,32.0
89.000828140,24.0
89.067673214,38.0
89.134518289,32.0
89.201363363,31.0
89.268208438,25.0
89.335053512,34.0
89.401898587,32.0
89.468743661,34.0
89.535588736,28.0
89.602433810,39.0
89.669278885,25.0
89.736123959,22.0
89.802969034,36.0
89.869814108,34.0
89.936659183,39.0
89.970081720,36.0