File: simple_graph/30 90 .03ss 30tps Mortan Salt.csv
[Measurement conditions]
Sample identification,
Comment - 1,"Configuration=Reflection-transmission spinner, Owner=User-1, Creation date=5/11/2015 1:51:45 PM"
Comment - 2,"Goniometer=Theta/Theta; Minimum step size 2Theta:0.0001; Minimum step size Omega:0.0001"
Comment - 3,"Sample stage=Reflection-transmission spinner; Minimum step size Phi:0.1"
Comment - 4,"Diffractometer system=EMPYREAN"
Comment - 5,"Measurement program=C:\PANalytical\Data Collector\Programs\Esin Scan.xrdmp, Identifier={545BE9EB-C830-47C9-A564-E4EDE9967014}"
Anode material,Cu
K-Alpha1 wavelength,1.5405980
K-Alpha2 wavelength,1.5444260
Ratio K-Alpha2/K-Alpha1,0.500
Divergence slit,Fixed,0.19mm
Monochromator used,NO
Generator voltage, 45
Tube current, 40
File date and time,29/Jan/2020 10:35
Unit cell,
h k l, 0 0 0
Scan axis,Gonio
Scan range,20.000000001,89.986792989
Scan step size,0.0334225
No. of points, 2094
Scan type,CONTINUOUS
Phi,271.6
Time per step,29.845
[Scan points]
Angle,Intensity
20.016711270,114.0
20.083556344,112.0
20.150401419,127.0
20.217246493,119.0
20.284091568,116.0
20.350936642,108.0
20.417781717,116.0
20.484626791,127.0
20.551471866,107.0
20.618316940,102.0
20.685162015,91.0
20.752007089,127.0
20.818852164,88.0
20.885697238,108.0
20.952542313,105.0
21.019387387,103.0
21.086232462,102.0
21.153077536,87.0
21.219922611,84.0
21.286767685,102.0
21.353612760,110.0
21.420457834,119.0
21.487302909,87.0
21.554147983,107.0
21.620993058,115.0
21.687838132,100.0
21.754683207,103.0
21.821528281,99.0
21.888373356,102.0
21.955218430,98.0
22.022063505,105.0
22.088908579,101.0
22.155753654,100.0
22.222598728,88.0
22.289443803,103.0
22.356288877,96.0
22.423133952,113.0
22.489979026,91.0
22.556824100,111.0
22.623669175,107.0
22.690514249,92.0
22.757359324,101.0
22.824204398,97.0
22.891049473,93.0
22.957894547,102.0
23.024739622,101.0
23.091584696,100.0
23.158429771,103.0
23.225274845,100.0
23.292119920,81.0
23.358964994,83.0
23.425810069,84.0
23.492655143,100.0
23.559500218,99.0
23.626345292,85.0
23.693190367,81.0
23.760035441,78.0
23.826880516,75.0
23.893725590,91.0
23.960570665,95.0
24.027415739,80.0
24.094260814,74.0
24.161105888,79.0
24.227950963,88.0
24.294796037,61.0
24.361641112,74.0
24.428486186,85.0
24.495331261,86.0
24.562176335,91.0
24.629021410,86.0
24.695866484,105.0
24.762711559,78.0
24.829556633,79.0
24.896401708,84.0
24.963246782,72.0
25.030091856,95.0
25.096936931,85.0
25.163782005,89.0
25.230627080,75.0
25.297472154,80.0
25.364317229,84.0
25.431162303,73.0
25.498007378,78.0
25.564852452,62.0
25.631697527,78.0
25.698542601,81.0
25.765387676,57.0
25.832232750,72.0
25.899077825,68.0
25.965922899,85.0
26.032767974,67.0
26.099613048,81.0
26.166458123,61.0
26.233303197,88.0
26.300148272,74.0
26.366993346,63.0
26.433838421,84.0
26.500683495,67.0
26.567528570,65.0
26.634373644,81.0
26.701218719,84.0
26.768063793,78.0
26.834908868,80.0
26.901753942,65.0
26.968599017,86.0
27.035444091,66.0
27.102289166,52.0
27.169134240,80.0
27.235979315,68.0
27.302824389,105.0
27.369669464,133.0
27.436514538,121.0
27.503359612,107.0
27.570204687,79.0
27.637049761,83.0
27.703894836,70.0
27.770739910,66.0
27.837584985,50.0
27.904430059,83.0
27.971275134,66.0
28.038120208,64.0
28.104965283,65.0
28.171810357,65.0
28.238655432,78.0
28.305500506,64.0
28.372345581,75.0
28.439190655,64.0
28.506035730,60.0
28.572880804,66.0
28.639725879,74.0
28.706570953,60.0
28.773416028,56.0
28.840261102,69.0
28.907106177,76.0
28.973951251,58.0
29.040796326,53.0
29.107641400,38.0
29.174486475,72.0
29.241331549,61.0
29.308176624,68.0
29.375021698,68.0
29.441866773,62.0
29.508711847,48.0
29.575556922,70.0
29.642401996,66.0
29.709247071,63.0
29.776092145,45.0
29.842937219,56.0
29.909782294,68.0
29.976627368,69.0
30.043472443,46.0
30.110317517,63.0
30.177162592,53.0
30.244007666,54.0
30.310852741,51.0
30.377697815,54.0
30.444542890,63.0
30.511387964,70.0
30.578233039,50.0
30.645078113,62.0
30.711923188,74.0
30.778768262,62.0
30.845613337,68.0
30.912458411,80.0
30.979303486,70.0
31.046148560,65.0
31.112993635,80.0
31.179838709,72.0
31.246683784,95.0
31.313528858,107.0
31.380373933,96.0
31.447219007,193.0
31.514064082,358.0
31.580909156,3376.0
31.647754231,5010.0
31.714599305,5674.0
31.781444380,16662.0
31.848289454,10640.0
31.915134529,816.0
31.981979603,314.0
32.048824678,186.0
32.115669752,154.0
32.182514827,113.0
32.249359901,100.0
32.316204975,97.0
32.383050050,77.0
32.449895124,79.0
32.516740199,84.0
32.583585273,69.0
32.650430348,68.0
32.717275422,54.0
32.784120497,64.0
32.850965571,56.0
32.917810646,45.0
32.984655720,57.0
33.051500795,45.0
33.118345869,43.0
33.185190944,42.0
33.252036018,53.0
33.318881093,36.0
33.385726167,55.0
33.452571242,51.0
33.519416316,56.0
33.586261391,51.0
33.653106465,39.0
33.719951540,40.0
33.786796614,42.0
33.853641689,54.0
33.920486763,56.0
33.987331838,38.0
34.054176912,46.0
34.121021987,48.0
34.187867061,48.0
34.254712136,50.0
34.321557210,46.0
34.388402285,39.0
34.455247359,39.0
34.522092434,40.0
34.588937508,41.0
34.655782583,34.0
34.722627657,43.0
34.789472731,34.0
34.856317806,33.0
34.923162880,36.0
34.990007955,43.0
35.056853029,40.0
35.123698104,22.0
35.190543178,41.0
35.257388253,26.0
35.324233327,29.0
35.391078402,46.0
35.457923476,44.0
35.524768551,48.0
35.591613625,38.0
35.658458700,46.0
35.725303774,36.0
35.792148849,56.0
35.858993923,28.0
35.925838998,33.0
35.992684072,46.0
36.059529147,30.0
36.126374221,33.0
36.193219296,39.0
36.260064370,38.0
36.326909445,43.0
36.393754519,28.0
36.460599594,34.0
36.527444668,30.0
36.594289743,37.0
36.661134817,31.0
36.727979892,37.0
36.794824966,28.0
36.861670041,30.0
36.928515115,24.0
36.995360190,28.0
37.062205264,42.0
37.129050339,24.0
37.195895413,27.0
37.262740487,38.0
37.329585562,36.0
37.396430636,33.0
37.463275711,38.0
37.530120785,39.0
37.596965860,24.0
37.663810934,34.0
37.730656009,28.0
37.797501083,41.0
37.864346158,37.0
37.931191232,24.0
37.998036307,33.0
38.064881381,39.0
38.131726456,31.0
38.198571530,34.0
38.265416605,37.0
38.332261679,21.0
38.399106754,30.0
38.465951828,31.0
38.532796903,25.0
38.599641977,32.0
38.666487052,39.0
38.733332126,26.0
38.800177201,32.0
38.867022275,36.0
38.933867350,24.0
39.000712424,33.0
39.067557499,30.0
39.134402573,32.0
39.201247648,32.0
39.268092722,36.0
39.334937797,36.0
39.401782871,30.0
39.468627946,37.0
39.535473020,32.0
39.602318095,33.0
39.669163169,30.0
39.736008243,27.0
39.802853318,36.0
39.869698392,18.0
39.936543467,27.0
40.003388541,28.0
40.070233616,29.0
40.137078690,26.0
40.203923765,29.0
40.270768839,29.0
40.337613914,26.0
40.404458988,34.0
40.471304063,34.0
40.538149137,36.0
40.604994212,37.0
40.671839286,40.0
40.738684361,32.0
40.805529435,33.0
40.872374510,32.0
40.939219584,29.0
41.006064659,32.0
41.072909733,34.0
41.139754808,34.0
41.206599882,22.0
41.273444957,38.0
41.340290031,30.0
41.407135106,32.0
41.473980180,32.0
41.540825255,26.0
41.607670329,27.0
41.674515404,32.0
41.741360478,19.0
41.808205553,26.0
41.875050627,19.0
41.941895702,29.0
42.008740776,19.0
42.075585851,42.0
42.142430925,34.0
42.209275999,31.0
42.276121074,29.0
42.342966148,42.0
42.409811223,25.0
42.476656297,24.0
42.543501372,32.0
42.610346446,24.0
42.677191521,32.0
42.744036595,31.0
42.810881670,42.0
42.877726744,27.0
42.944571819,40.0
43.011416893,19.0
43.078261968,31.0
43.145107042,28.0
43.211952117,31.0
43.278797191,27.0
43.345642266,27.0
43.412487340,17.0
43.479332415,26.0
43.546177489,28.0
43.613022564,33.0
43.679867638,30.0
43.746712713,24.0
43.813557787,27.0
43.880402862,29.0
43.947247936,26.0
44.014093011,20.0
44.080938085,27.0
44.147783160,26.0
44.214628234,31.0
44.281473309,24.0
44.348318383,32.0
44.415163458,39.0
44.482008532,27.0
44.548853607,33.0
44.615698681,28.0
44.682543755,52.0
44.749388830,34.0
44.816233904,32.0
44.883078979,34.0
44.949924053,45.0
45.016769128,32.0
45.083614202,48.0
45.150459277,44.0
45.217304351,72.0
45.284149426,419.0
45.350994500,405.0
45.417839575,727.0
45.484684649,1851.0
45.551529724,1206.0
45.618374798,965.0
45.685219873,400.0
45.752064947,110.0
45.818910022,67.0
45.885755096,53.0
45.952600171,37.0
46.019445245,40.0
46.086290320,37.0
46.153135394,44.0
46.219980469,29.0
46.286825543,37.0
46.353670618,44.0
46.420515692,28.0
46.487360767,20.0
46.554205841,31.0
46.621050916,29.0
46.687895990,32.0
46.754741065,22.0
46.821586139,25.0
46.888431214,28.0
46.955276288,30.0
47.022121362,30.0
47.088966437,32.0
47.155811511,40.0
47.222656586,21.0
47.289501660,36.0
47.356346735,25.0
47.423191809,24.0
47.490036884,37.0
47.556881958,28.0
47.623727033,36.0
47.690572107,25.0
47.757417182,34.0
47.824262256,28.0
47.891107331,28.0
47.957952405,31.0
48.024797480,30.0
48.091642554,17.0
48.158487629,20.0
48.225332703,28.0
48.292177778,31.0
48.359022852,37.0
48.425867927,18.0
48.492713001,15.0
48.559558076,20.0
48.626403150,26.0
48.693248225,16.0
48.760093299,29.0
48.826938374,26.0
48.893783448,17.0
48.960628523,24.0
49.027473597,12.0
49.094318672,21.0
49.161163746,24.0
49.228008821,20.0
49.294853895,27.0
49.361698970,17.0
49.428544044,27.0
49.495389118,30.0
49.562234193,28.0
49.629079267,25.0
49.695924342,27.0
49.762769416,29.0
49.829614491,22.0
49.896459565,28.0
49.963304640,17.0
50.030149714,20.0
50.096994789,28.0
50.163839863,25.0
50.230684938,17.0
50.297530012,22.0
50.364375087,22.0
50.431220161,32.0
50.498065236,22.0
50.564910310,21.0
50.631755385,14.0
50.698600459,16.0
50.765445534,16.0
50.832290608,22.0
50.899135683,16.0
50.965980757,25.0
51.032825832,25.0
51.099670906,13.0
51.166515981,19.0
51.233361055,22.0
51.300206130,13.0
51.367051204,18.0
51.433896279,20.0
51.500741353,14.0
51.567586428,17.0
51.634431502,20.0
51.701276577,25.0
51.768121651,22.0
51.834966726,24.0
51.901811800,34.0
51.968656874,29.0
52.035501949,24.0
52.102347023,25.0
52.169192098,20.0
52.236037172,26.0
52.302882247,20.0
52.369727321,26.0
52.436572396,17.0
52.503417470,25.0
52.570262545,18.0
52.637107619,30.0
52.703952694,21.0
52.770797768,18.0
52.837642843,18.0
52.904487917,26.0
52.971332992,24.0
53.038178066,16.0
53.105023141,21.0
53.171868215,24.0
53.238713290,21.0
53.305558364,22.0
53.372403439,16.0
53.439248513,30.0
53.506093588,22.0
53.572938662,21.0
53.639783737,21.0
53.706628811,31.0
53.773473886,64.0
53.840318960,66.0
53.907164035,129.0
53.974009109,61.0
54.040854184,89.0
54.107699258,50.0
54.174544333,22.0
54.241389407,18.0
54.308234482,28.0
54.375079556,24.0
54.441924630,21.0
54.508769705,17.0
54.575614779,30.0
54.642459854,21.0
54.709304928,13.0
54.776150003,26.0
54.842995077,27.0
54.909840152,13.0
54.976685226,24.0
55.043530301,17.0
55.110375375,20.0
55.177220450,17.0
55.244065524,36.0
55.310910599,26.0
55.377755673,22.0
55.444600748,15.0
55.511445822,29.0
55.578290897,21.0
55.645135971,25.0
55.711981046,26.0
55.778826120,17.0
55.845671195,16.0
55.912516269,22.0
55.979361344,18.0
56.046206418,30.0
56.113051493,28.0
56.179896567,22.0
56.246741642,30.0
56.313586716,39.0
56.380431791,87.0
56.447276865,66.0
56.514121940,100.0
56.580967014,72.0
56.647812089,56.0
56.714657163,44.0
56.781502238,22.0
56.848347312,21.0
56.915192386,31.0
56.982037461,18.0
57.048882535,16.0
57.115727610,15.0
57.182572684,12.0
57.249417759,16.0
57.316262833,21.0
57.383107908,18.0
57.449952982,13.0
57.516798057,25.0
57.583643131,24.0
57.650488206,18.0
57.717333280,20.0
57.784178355,22.0
57.851023429,12.0
57.917868504,25.0
57.984713578,22.0
58.051558653,14.0
58.118403727,15.0
58.185248802,19.0
58.252093876,18.0
58.318938951,16.0
58.385784025,24.0
58.452629100,20.0
58.519474174,17.0
58.586319249,20.0
58.653164323,10.0
58.720009398,19.0
58.786854472,21.0
58.853699547,19.0
58.920544621,21.0
58.987389696,17.0
59.054234770,20.0
59.121079845,14.0
59.187924919,24.0
59.254769994,18.0
59.321615068,25.0
59.388460142,16.0
59.455305217,27.0
59.522150291,18.0
59.588995366,27.0
59.655840440,17.0
59.722685515,16.0
59.789530589,16.0
59.856375664,15.0
59.923220738,17.0
59.990065813,19.0
60.056910887,14.0
60.123755962,15.0
60.190601036,18.0
60.257446111,18.0
60.324291185,20.0
60.391136260,15.0
60.457981334,10.0
60.524826409,12.0
60.591671483,19.0
60.658516558,18.0
60.725361632,18.0
60.792206707,20.0
60.859051781,21.0
60.925896856,25.0
60.992741930,20.0
61.059587005,18.0
61.126432079,28.0
61.193277154,20.0
61.260122228,28.0
61.326967303,16.0
61.393812377,24.0
61.460657452,18.0
61.527502526,18.0
61.594347601,20.0
61.661192675,19.0
61.728037750,21.0
61.794882824,17.0
61.861727898,24.0
61.928572973,28.0
61.995418047,19.0
62.062263122,18.0
62.129108196,24.0
62.195953271,28.0
62.262798345,26.0
62.329643420,22.0
62.396488494,27.0
62.463333569,29.0
62.530178643,18.0
62.597023718,27.0
62.663868792,25.0
62.730713867,19.0
62.797558941,16.0
62.864404016,18.0
62.931249090,26.0
62.998094165,24.0
63.064939239,15.0
63.131784314,16.0
63.198629388,18.0
63.265474463,22.0
63.332319537,26.0
63.399164612,27.0
63.466009686,18.0
63.532854761,16.0
63.599699835,19.0
63.666544910,27.0
63.733389984,24.0
63.800235059,26.0
63.867080133,25.0
63.933925208,18.0
64.000770282,16.0
64.067615357,27.0
64.134460431,25.0
64.201305505,15.0
64.268150580,18.0
64.334995654,17.0
64.401840729,22.0
64.468685803,18.0
64.535530878,26.0
64.602375952,26.0
64.669221027,20.0
64.736066101,22.0
64.802911176,26.0
64.869756250,21.0
64.936601325,28.0
65.003446399,30.0
65.070291474,24.0
65.137136548,26.0
65.203981623,22.0
65.270826697,22.0
65.337671772,22.0
65.404516846,21.0
65.471361921,16.0
65.538206995,36.0
65.605052070,16.0
65.671897144,33.0
65.738742219,28.0
65.805587293,25.0
65.872432368,28.0
65.939277442,39.0
66.006122517,54.0
66.072967591,80.0
66.139812666,445.0
66.206657740,270.0
66.273502815,1299.0
66.340347889,382.0
66.407192964,238.0
66.474038038,507.0
66.540883113,76.0
66.607728187,54.0
66.674573261,52.0
66.741418336,37.0
66.808263410,29.0
66.875108485,22.0
66.941953559,20.0
67.008798634,28.0
67.075643708,24.0
67.142488783,27.0
67.209333857,33.0
67.276178932,26.0
67.343024006,27.0
67.409869081,17.0
67.476714155,28.0
67.543559230,17.0
67.610404304,32.0
67.677249379,20.0
67.744094453,20.0
67.810939528,27.0
67.877784602,30.0
67.944629677,18.0
68.011474751,17.0
68.078319826,19.0
68.145164900,24.0
68.212009975,19.0
68.278855049,12.0
68.345700124,20.0
68.412545198,26.0
68.479390273,18.0
68.546235347,17.0
68.613080422,18.0
68.679925496,18.0
68.746770571,22.0
68.813615645,18.0
68.880460720,22.0
68.947305794,19.0
69.014150869,14.0
69.080995943,13.0
69.147841017,31.0
69.214686092,26.0
69.281531166,17.0
69.348376241,12.0
69.415221315,14.0
69.482066390,20.0
69.548911464,26.0
69.615756539,15.0
69.682601613,22.0
69.749446688,20.0
69.816291762,24.0
69.883136837,42.0
69.949981911,28.0
70.016826986,22.0
70.083672060,17.0
70.150517135,19.0
70.217362209,21.0
70.284207284,21.0
70.351052358,21.0
70.417897433,22.0
70.484742507,26.0
70.551587582,22.0
70.618432656,28.0
70.685277731,28.0
70.752122805,18.0
70.818967880,16.0
70.885812954,18.0
70.952658029,14.0
71.019503103,30.0
71.086348178,16.0
71.153193252,25.0
71.220038327,19.0
71.286883401,18.0
71.353728476,27.0
71.420573550,16.0
71.487418625,20.0
71.554263699,19.0
71.621108773,32.0
71.687953848,20.0
71.754798922,24.0
71.821643997,14.0
71.888489071,20.0
71.955334146,16.0
72.022179220,25.0
72.089024295,24.0
72.155869369,33.0
72.222714444,19.0
72.289559518,29.0
72.356404593,22.0
72.423249667,24.0
72.490094742,24.0
72.556939816,22.0
72.623784891,29.0
72.690629965,24.0
72.757475040,15.0
72.824320114,30.0
72.891165189,15.0
72.958010263,36.0
73.024855338,41.0
73.091700412,39.0
73.158545487,44.0
73.225390561,44.0
73.292235636,28.0
73.359080710,29.0
73.425925785,26.0
73.492770859,17.0
73.559615934,19.0
73.626461008,19.0
73.693306083,26.0
73.760151157,27.0
73.826996232,19.0
73.893841306,25.0
73.960686381,20.0
74.027531455,21.0
74.094376529,22.0
74.161221604,21.0
74.228066678,34.0
74.294911753,21.0
74.361756827,28.0
74.428601902,19.0
74.495446976,27.0
74.562292051,25.0
74.629137125,21.0
74.695982200,19.0
74.762827274,28.0
74.829672349,25.0
74.896517423,21.0
74.963362498,29.0
75.030207572,33.0
75.097052647,90.0
75.163897721,186.0
75.230742796,264.0
75.297587870,214.0
75.364432945,168.0
75.431278019,182.0
75.498123094,176.0
75.564968168,77.0
75.631813243,55.0
75.698658317,81.0
75.765503392,42.0
75.832348466,25.0
75.899193541,36.0
75.966038615,22.0
76.032883690,25.0
76.099728764,27.0
76.166573839,24.0
76.233418913,29.0
76.300263988,20.0
76.367109062,22.0
76.433954137,17.0
76.500799211,22.0
76.567644285,24.0
76.634489360,25.0
76.701334434,21.0
76.768179509,25.0
76.835024583,24.0
76.901869658,27.0
76.968714732,30.0
77.035559807,22.0
77.102404881,25.0
77.169249956,26.0
77.236095030,25.0
77.302940105,25.0
77.369785179,17.0
77.436630254,29.0
77.503475328,29.0
77.570320403,21.0
77.637165477,16.0
77.704010552,24.0
77.770855626,20.0
77.837700701,19.0
77.904545775,27.0
77.971390850,19.0
78.038235924,17.0
78.105080999,19.0
78.171926073,24.0
78.238771148,24.0
78.305616222,22.0
78.372461297,14.0
78.439306371,10.0
78.506151446,20.0
78.572996520,15.0
78.639841595,20.0
78.706686669,17.0
78.773531744,17.0
78.840376818,18.0
78.907221893,16.0
78.974066967,21.0
79.040912041,14.0
79.107757116,19.0
79.174602190,13.0
79.241447265,20.0
79.308292339,15.0
79.375137414,14.0
79.441982488,19.0
79.508827563,25.0
79.575672637,22.0
79.642517712,18.0
79.709362786,22.0
79.776207861,29.0
79.843052935,22.0
79.909898010,10.0
79.976743084,25.0
80.043588159,24.0
80.110433233,18.0
80.177278308,14.0
80.244123382,30.0
80.310968457,20.0
80.377813531,21.0
80.444658606,17.0
80.511503680,19.0
80.578348755,24.0
80.645193829,18.0
80.712038904,16.0
80.778883978,16.0
80.845729053,30.0
80.912574127,20.0
80.979419202,25.0
81.046264276,21.0
81.113109351,22.0
81.179954425,20.0
81.246799500,22.0
81.313644574,16.0
81.380489648,19.0
81.447334723,15.0
81.514179797,22.0
81.581024872,17.0
81.647869946,17.0
81.714715021,12.0
81.781560095,18.0
81.848405170,22.0
81.915250244,13.0
81.982095319,12.0
82.048940393,19.0
82.115785468,13.0
82.182630542,28.0
82.249475617,19.0
82.316320691,25.0
82.383165766,27.0
82.450010840,21.0
82.516855915,18.0
82.583700989,28.0
82.650546064,19.0
82.717391138,22.0
82.784236213,32.0
82.851081287,21.0
82.917926362,18.0
82.984771436,28.0
83.051616511,29.0
83.118461585,26.0
83.185306660,31.0
83.252151734,24.0
83.318996809,30.0
83.385841883,32.0
83.452686958,36.0
83.519532032,37.0
83.586377107,34.0
83.653222181,42.0
83.720067256,58.0
83.786912330,171.0
83.853757404,672.0
83.920602479,471.0
83.987447553,317.0
84.054292628,245.0
84.121137702,453.0
84.187982777,251.0
84.254827851,197.0
84.321672926,85.0
84.388518000,53.0
84.455363075,39.0
84.522208149,36.0
84.589053224,22.0
84.655898298,19.0
84.722743373,30.0
84.789588447,19.0
84.856433522,22.0
84.923278596,31.0
84.990123671,25.0
85.056968745,16.0
85.123813820,15.0
85.190658894,22.0
85.257503969,26.0
85.324349043,20.0
85.391194118,14.0
85.458039192,22.0
85.524884267,24.0
85.591729341,19.0
85.658574416,25.0
85.725419490,30.0
85.792264565,37.0
85.859109639,30.0
85.925954714,19.0
85.992799788,24.0
86.059644863,29.0
86.126489937,18.0
86.193335012,27.0
86.260180086,22.0
86.327025160,29.0
86.393870235,24.0
86.460715309,32.0
86.527560384,18.0
86.594405458,16.0
86.661250533,16.0
86.728095607,24.0
86.794940682,19.0
86.861785756,20.0
86.928630831,26.0
86.995475905,17.0
87.062320980,16.0
87.129166054,25.0
87.196011129,25.0
87.262856203,19.0
87.329701278,24.0
87.396546352,34.0
87.463391427,19.0
87.530236501,22.0
87.597081576,13.0
87.663926650,9.0
87.730771725,21.0
87.797616799,13.0
87.864461874,20.0
87.931306948,12.0
87.998152023,28.0
88.064997097,8.0
88.131842172,18.0
88.198687246,19.0
88.265532321,17.0
88.332377395,22.0
88.399222470,13.0
88.466067544,8.0
88.532912619,20.0
88.599757693,22.0
88.666602768,16.0
88.733447842,21.0
88.800292916,18.0
88.867137991,18.0
88.933983065,20.0
89.000828140,19.0
89.067673214,19.0
89.134518289,15.0
89.201363363,21.0
89.268208438,15.0
89.335053512,15.0
89.401898587,14.0
89.468743661,17.0
89.535588736,26.0
89.602433810,21.0
89.669278885,28.0
89.736123959,20.0
89.802969034,17.0
89.869814108,28.0
89.936659183,17.0
89.970081720,22.0